Workbook
Name FERIADOS: PARAMETROS!$A$2:$A$1551

Sheet DIC_TABLAS
A1: DATASET | B1: DESCRIPCION / INSTRUCCIONES
A2: =IFERROR(__xludf.DUMMYFUNCTION("QUERY({IMPORTRANGE(""1P0oKwzKbn6LJXrlUQ38ebfDyD6GcN8gtDfznV-VcUpg"",""DIC_TABLAS!A$2:D"")},""SELECT Col2, Col3 WHERE Col1 = 'AMBITO 3'"")"),"1) Multas coercitivas") -> 1) Multas coercitivas | B2: =IFERROR(__xludf.DUMMYFUNCTION("""COMPUTED_VALUE"""),"Esta base debe contener los proyectos de multas coercitivas.") -> Esta base debe contener los proyectos de multas coercitivas.
A3: =IFERROR(__xludf.DUMMYFUNCTION("""COMPUTED_VALUE"""),"2) Etapas") -> 2) Etapas | B3: =IFERROR(__xludf.DUMMYFUNCTION("""COMPUTED_VALUE"""),"Esta base debe contener las diferentes etapas de la elaboración de una multa coercitiva.") -> Esta base debe contener las diferentes etapas de la elaboración de una multa coercitiva.

Sheet DIC_VARIABLES
A1: DATASET | B1: SECCION | C1: CAMPO EN BD | D1: CODIGO CAMPO | E1: CAMPO NO PUBLICABLE | F1: NO PUBLICABLE PERO NECESARIO (CSEP) | G1: VARIABLES DE LLENADO MINIMO | H1: DESCRIPCION | I1: TIPO DE VARIABLE
A2: =IFERROR(__xludf.DUMMYFUNCTION("QUERY({IMPORTRANGE(""1GGHB-7IvEqjPs32eZ4K5cqTwzDZk9toJ9gAmRWrDwos"",""DIC_VARIABLES!A$2:J"")},""SELECT Col2, Col3, Col4, Col5, Col6, Col7, Col8, Col9, Col10 WHERE Col1 = 'AMBITO 3'"")"),"#REF!") -> #REF!

Sheet 1) Multas coercitivas
A1: CÓDIGOS | C1: ESTADO | E1: INFORMACIÓN GENERAL | I1: ETAPA DE DESCARGOS | Q1: ETAPA ANÁLISIS DE DESCARGOS | Y1: RESULTADO DEL PROYECTO | Z1: ETAPAS DE REGISTRO DE LA MC | AA1: IMPOSICIÓN DE MULTA COERCITIVA | AH1: SEGUIMIENTO DE MULTA | AL1: COBRANZA | AR1: AUXILIARES
A2: CÓDIGO DE LA MEDIDA ADMINISTRATIVA | B2: CÓDIGO DE PROYECTO DE MULTA COERCITIVA | C2: JEFE DE EQUIPO RESPONSABLE | D2: ETAPAS DE REGISTRO DEL PROYECTO | E2: N° DE PROYECTO | F2: COORDINACIÓN | G2: ADMINISTRADO | H2: UNIDAD FISCALIZABLE | I2: EXPEDIENTE CON EL INFORME DE DECLARACIÓN DEL INCUMPLIMIENTO | J2: N° DE CARTA QUE REQUIERE DESCARGOS | K2: FECHA DE NOTIFICACIÓN | L2: FECHA DE VENCIMIENTO | M2: ¿PRESENTÓ DESCARGOS EL ADMINISTRADO? | N2: FECHA DE RESPUESTA DEL ADMINISTRADO | O2: DOCUMENTO SIGED | P2: ESTADO DE DESCARGOS | Q2: FECHA DE INICIO DE ANÁLISIS | R2: ¿REQUIERE VERIFICACIÓN EN CAMPO? | S2: FECHA DE VERIFICACIÓN EN CAMPO | T2: FECHA FIN DE ANÁLISIS | U2: ¿AMERITA MULTA? | V2: N° DE DOCUMENTO EN EL QUE SE INDICA QUE NO AMERITA | W2: FECHA DOCUMENTO EN EL QUE SE INDICA QUE NO AMERITA MULTA | X2: MOTIVO POR EL CUAL NO AMERITA MULTA COERCITIVA | Y2: RESULTADO DEL PROYECTO | Z2: ETAPAS DE REGISTRO DE LA MC | AA2: EXPEDIENTE CON LA RESOLUCIÓN DE MC | AB2: N° DE RESOLUCIÓN DE MC | AC2: FECHA DE FIRMA DE RESOLUCIÓN DE MC | AD2: FECHA DE NOTIFICACIÓN DE RESOLUCIÓN DE MC | AE2: FECHA DE VENCIMIENTO DE MULTA | AF2: MULTA EN UIT | AG2: MULTA EN SOLES | AH2: RECORDATORIO NUEVO SEGUIMIENTO (POST MULTA COERCITIVA) | AI2: FECHA DE VERIFICACIÓN POST MULTA COERCITIVA | AJ2: DOCUMENTO DE VERIFICACIÓN DE MULTA | AK2: EXPEDIENTE SIGED DEL DOCUMENTO | AL2: ESTADO DE LA MULTA | AM2: FECHA DE PAGO | AN2: MEMORANDO DE TRASLADO A EJECUCIÓN FORZOSA | AO2: FECHA DE REMISIÓN DEL MEMORANDO | AP2: SIGED | AQ2: ESTADO DEL PAGO DE LA MULTA | AR2: AUX FINALIZADO | AS2: CÓDIGO DE LA MEDIDA ADMINISTRATIVA AUX | AT2: ESTADO AUX DE MULTA COERCITIVA | AU2: ÚLTIMA RESOLUCIÓN DE MULTA COERCITIVA | AV2: FECHA DE NOTIFICACIÓN DE LA ÚLTIMA RESOLUCIÓN DE MULTA COERCITIVA
A3: COD_MA | B3: COD_PROY_MC | C3: JEFE | D3: ETA_REG_PROY_MC | E3: N_PROY_MC | F3: COORD | G3: ADM | H3: UF | I3: EXP_INF_INCUMP | J3: N_CARTA_DCG | K3: FN_MC | L3: F_VENC_DCG | M3: PRESENT_DCG_ADM | N3: F_RPTA_ADM | O3: DOC_SIGED | P3: EST_DCG | Q3: F_INIC_ANALISIS | R3: REQ_VERIF_CAMPO | S3: F_VERIF_CAMPO | T3: F_FIN_ANALISIS | U3: AMERIT_MC | V3: N_DOC_NO_AMERIT | W3: F_DOC_NO_AMERIT | X3: MOTIVO_NO_AMERIT | Y3: RESULT_PROY_MC | Z3: ETA_REG_MC | AA3: EXP_RES_MC | AB3: N_RES_MC | AC3: F_FIRMA_RES_MC | AD3: FN_RES_MC | AE3: F_VENC_MC | AF3: MULTA_UIT | AG3: MULTA_S | AH3: RECORD_SEG | AI3: F_VERIF_POST_MC | AJ3: DOC_VERIF_MC | AK3: EXP_SIGED_DOC | AL3: ESTADO_MC | AM3: F_PAGO | AN3: MEMO_EF | AO3: F_REMIS | AP3: SIGED | AQ3: ESTADO_PAGO_MC | AR3: AUX_FIN_MC | AS3: AUX_COD_MA | AT3: AUX_EST_MC | AU3: URESOL_MC | AV3: FN_URESOL_MC
A4: 0136-2021-0012-2022-1-CAGR | B4: =IF(A4="","",IF(E4="","INDICAR NÚMERO DE PROYECTO",CONCATENATE("MULTA COERCITIVA - ",E4,"/",F4))) -> MULTA COERCITIVA - 1/CÓDIGO DE EXPEDIENTE INVÁLIDO | C4: PEÑA, AGUSTÍN | D4: =IF(A4="","",IF(AL4<>"","EN ETAPA DE COBRANZA",IF(AH4<>"","EN SEGUIMIENTO DE MULTA",IF(AB4<>"","EN IMPOISICIÓN DE MULTA",IF(Q4<>"","EN ETAPA DE ÁNALISIS DE DESCARGOS",IF(OR(P5="VENCIDO", P5="EN PLAZO"),"EN ETAPA DE DESCARGOS","EN ETAPA DE DESCARGOS")))))) -> EN ETAPA DE COBRANZA | E4: 1 | F4: {=IF($A4="","",IFERROR(INDEX(MA_INDIVIDUALES!C$2:C923, MATCH($A4,MA_INDIVIDUALES!$B$2:$B923,0),1),"CÓDIGO DE EXPEDIENTE INVÁLIDO"))} -> CÓDIGO DE EXPEDIENTE INVÁLIDO | G4: {=IF($A4="","",IFERROR(INDEX(MA_INDIVIDUALES!K$2:K923, MATCH($A4,MA_INDIVIDUALES!$B$2:$B923,0),1),"CÓDIGO DE EXPEDIENTE INVÁLIDO"))} -> CÓDIGO DE EXPEDIENTE INVÁLIDO | H4: {=IF($A4="","",IFERROR(INDEX(MA_INDIVIDUALES!L$2:L923, MATCH($A4,MA_INDIVIDUALES!$B$2:$B923,0),1),"CÓDIGO DE EXPEDIENTE INVÁLIDO"))} -> CÓDIGO DE EXPEDIENTE INVÁLIDO | I4: 0237-2022-DSAP-CAGR | J4: 0240-2023-OEFA/DSAP | K4: 44980 | L4: =IF(A4="","",IF(K4="","",_xlfn.WORKDAY.INTL(K4,5,1,FERIADOS))) -> 44987 | M4: NO | P4: =IF(A4="","",IF(M4="NO","NO PRESENTÓ DESCARGOS",IF(N4="",IF(TODAY()<=L4,"EN PLAZO","VENCIDO"),IF(N4<=L4,"PRESENTADO EN PLAZO","PRESENTADO FUERA DE PLAZO")))) -> NO PRESENTÓ DESCARGOS | U4: SI | Y4: =IF(A4="","",IF(U4="SI","ELABORAR MC",IF(U4="NO","NO AMERITA ELABORAR MC","EN PROCESO"))) -> ELABORAR MC | Z4: =IF(A4="","",IF(AND(AR4=-1,Y4="ELABORAR MC"),"SIN REGISTRO DE ETAPAS",IF(AND(AR4=0,Y4="ELABORAR MC"),"EN PROCESO",IF(AND(AR4=1,Y4="ELABORAR MC",AB4=""),"EN ESPERA DE REGISTRO DE RESOLUCIÓN",IF(AND(AR4=1,Y4="ELABORAR MC",AB4<>""),"TERMINADO",IF(OR(Y4="NO AMERITA MC",Y4="EN PROCESO"),"","")))))) -> SIN REGISTRO DE ETAPAS | AA4: 0237-2022-DSAP-CAGR | AB4: 0018-2023-OEFA/DSAP | AC4: 45001 | AD4: 45002 | AE4: =IF(U4="","",IF(AD4="","",_xlfn.WORKDAY.INTL(AD4,7,1,FERIADOS))) -> 45013 | AF4: 15 | AG4: {=IF(A4="","",IF(AF4="","",AF4*INDEX(PARAMETROS!F$2:F1067,MATCH(YEAR(AC4),PARAMETROS!E$2:E1067,0),1)))} -> #N/A | AL4: INCUMPLIDO | AN4: 0689-2023-OEFA/DSAP | AO4: 45029 | AP4: 2023-I01-012453 | AQ4: =IF($A4="","",IF(OR(AB4="",AL4="EN EJECUCIÓN"),"EN PROCESO", IF(AE4="","INDICAR FECHA DE NOTIFICACIÓN",IF(AM4="","NO PAGÓ MULTA",IF(AM4="",IF(TODAY()<=AE4,"EN PLAZO","VENCIDO"),IF(AM4<=AE4,"PAGADO EN PLAZO","PAGADO FUERA DE PLAZO")))))) -> NO PAGÓ MULTA | AR4: {=IF(A4="","",IFERROR(INDEX('2) Etapas'!L$3:L923,MATCH(B4,'2) Etapas'!$A$4:$A923,0),1),-1))} -> -1 | AS4: =IF(A4="","",A4) -> 0136-2021-0012-2022-1-CAGR | AT4: =IF(A4="","",IF(AU4="","MULTA EN ELABORACIÓN", "MULTA IMPUESTA")) -> MULTA IMPUESTA | AU4: =IF(OR($A4="",$AB4="", $AC4=""),"", INDEX($AB$4:$AB923,MATCH(CONCATENATE($A4,$AV4),$A$4:$A923&$AC$4:$AC923,0),1)) -> 0018-2023-OEFA/DSAP | AV4: {=IF(OR($A4="",$AB4="", $AC4=""),"",MAXA(IF($A4=$A$4:$A923,$AC$4:$AC923)))} -> 45001
A5: 0016-2022-ACTA 0002-1-CAGR | B5: =IF(A5="","",IF(E5="","INDICAR NÚMERO DE PROYECTO",CONCATENATE("MULTA COERCITIVA - ",E5,"/",F5))) -> MULTA COERCITIVA - 2/CÓDIGO DE EXPEDIENTE INVÁLIDO | C5: PEÑA, AGUSTÍN | D5: =IF(A5="","",IF(AL5<>"","EN ETAPA DE COBRANZA",IF(AH5<>"","EN SEGUIMIENTO DE MULTA",IF(AB5<>"","EN IMPOISICIÓN DE MULTA",IF(Q5<>"","EN ETAPA DE ÁNALISIS DE DESCARGOS",IF(OR(P6="VENCIDO", P6="EN PLAZO"),"EN ETAPA DE DESCARGOS","EN ETAPA DE DESCARGOS")))))) -> EN ETAPA DE COBRANZA | E5: 2 | F5: {=IF($A5="","",IFERROR(INDEX(MA_INDIVIDUALES!C$2:C923, MATCH($A5,MA_INDIVIDUALES!$B$2:$B923,0),1),"CÓDIGO DE EXPEDIENTE INVÁLIDO"))} -> CÓDIGO DE EXPEDIENTE INVÁLIDO | G5: {=IF($A5="","",IFERROR(INDEX(MA_INDIVIDUALES!K$2:K923, MATCH($A5,MA_INDIVIDUALES!$B$2:$B923,0),1),"CÓDIGO DE EXPEDIENTE INVÁLIDO"))} -> CÓDIGO DE EXPEDIENTE INVÁLIDO | H5: {=IF($A5="","",IFERROR(INDEX(MA_INDIVIDUALES!L$2:L923, MATCH($A5,MA_INDIVIDUALES!$B$2:$B923,0),1),"CÓDIGO DE EXPEDIENTE INVÁLIDO"))} -> CÓDIGO DE EXPEDIENTE INVÁLIDO | I5: 0011-2023-DSAP-CAGR | J5: 0498-2023-OEFA/DSAP | K5: 45028 | L5: =IF(A5="","",IF(K5="","",_xlfn.WORKDAY.INTL(K5,5,1,FERIADOS))) -> 45035 | M5: NO | P5: =IF(A5="","",IF(M5="NO","NO PRESENTÓ DESCARGOS",IF(N5="",IF(TODAY()<=L5,"EN PLAZO","VENCIDO"),IF(N5<=L5,"PRESENTADO EN PLAZO","PRESENTADO FUERA DE PLAZO")))) -> NO PRESENTÓ DESCARGOS | U5: SI | Y5: =IF(A5="","",IF(U5="SI","ELABORAR MC",IF(U5="NO","NO AMERITA ELABORAR MC","EN PROCESO"))) -> ELABORAR MC | Z5: =IF(A5="","",IF(AND(AR5=-1,Y5="ELABORAR MC"),"SIN REGISTRO DE ETAPAS",IF(AND(AR5=0,Y5="ELABORAR MC"),"EN PROCESO",IF(AND(AR5=1,Y5="ELABORAR MC",AB5=""),"EN ESPERA DE REGISTRO DE RESOLUCIÓN",IF(AND(AR5=1,Y5="ELABORAR MC",AB5<>""),"TERMINADO",IF(OR(Y5="NO AMERITA MC",Y5="EN PROCESO"),"","")))))) -> SIN REGISTRO DE ETAPAS | AA5: 0011-2023-DSAP-CAGR | AB5: 0126-2023-OEFA/DSAP | AC5: 45110 | AD5: 45111 | AE5: =IF(U5="","",IF(AD5="","",_xlfn.WORKDAY.INTL(AD5,7,1,FERIADOS))) -> 45120 | AF5: 22.5 | AG5: {=IF(A5="","",IF(AF5="","",AF5*INDEX(PARAMETROS!F$2:F1068,MATCH(YEAR(AC5),PARAMETROS!E$2:E1068,0),1)))} -> #N/A | AL5: INCUMPLIDO | AN5: 1421-2023-OEFA/DSAP | AO5: 45124 | AP5: 2023-I01-025671 | AQ5: =IF($A5="","",IF(OR(AB5="",AL5="EN EJECUCIÓN"),"EN PROCESO", IF(AE5="","INDICAR FECHA DE NOTIFICACIÓN",IF(AM5="","NO PAGÓ MULTA",IF(AM5="",IF(TODAY()<=AE5,"EN PLAZO","VENCIDO"),IF(AM5<=AE5,"PAGADO EN PLAZO","PAGADO FUERA DE PLAZO")))))) -> NO PAGÓ MULTA | AR5: {=IF(A5="","",IFERROR(INDEX('2) Etapas'!L$3:L923,MATCH(B5,'2) Etapas'!$A$4:$A923,0),1),-1))} -> -1 | AS5: =IF(A5="","",A5) -> 0016-2022-ACTA 0002-1-CAGR | AT5: =IF(A5="","",IF(AU5="","MULTA EN ELABORACIÓN", "MULTA IMPUESTA")) -> MULTA IMPUESTA | AU5: =IF(OR($A5="",$AB5="", $AC5=""),"", INDEX($AB$4:$AB924,MATCH(CONCATENATE($A5,$AV5),$A$4:$A924&$AC$4:$AC924,0),1)) -> 0126-2023-OEFA/DSAP | AV5: {=IF(OR($A5="",$AB5="", $AC5=""),"",MAXA(IF($A5=$A$4:$A923,$AC$4:$AC923)))} -> 45110
A6: 0016-2022-ACTA 0002-2-CAGR | B6: =IF(A6="","",IF(E6="","INDICAR NÚMERO DE PROYECTO",CONCATENATE("MULTA COERCITIVA - ",E6,"/",F6))) -> MULTA COERCITIVA - 2/CÓDIGO DE EXPEDIENTE INVÁLIDO | C6: PEÑA, AGUSTÍN | D6: =IF(A6="","",IF(AL6<>"","EN ETAPA DE COBRANZA",IF(AH6<>"","EN SEGUIMIENTO DE MULTA",IF(AB6<>"","EN IMPOISICIÓN DE MULTA",IF(Q6<>"","EN ETAPA DE ÁNALISIS DE DESCARGOS",IF(OR(P7="VENCIDO", P7="EN PLAZO"),"EN ETAPA DE DESCARGOS","EN ETAPA DE DESCARGOS")))))) -> EN ETAPA DE COBRANZA | E6: 2 | F6: {=IF($A6="","",IFERROR(INDEX(MA_INDIVIDUALES!C$2:C923, MATCH($A6,MA_INDIVIDUALES!$B$2:$B923,0),1),"CÓDIGO DE EXPEDIENTE INVÁLIDO"))} -> CÓDIGO DE EXPEDIENTE INVÁLIDO | G6: {=IF($A6="","",IFERROR(INDEX(MA_INDIVIDUALES!K$2:K923, MATCH($A6,MA_INDIVIDUALES!$B$2:$B923,0),1),"CÓDIGO DE EXPEDIENTE INVÁLIDO"))} -> CÓDIGO DE EXPEDIENTE INVÁLIDO | H6: {=IF($A6="","",IFERROR(INDEX(MA_INDIVIDUALES!L$2:L923, MATCH($A6,MA_INDIVIDUALES!$B$2:$B923,0),1),"CÓDIGO DE EXPEDIENTE INVÁLIDO"))} -> CÓDIGO DE EXPEDIENTE INVÁLIDO | I6: 0011-2023-DSAP-CAGR | J6: 0498-2023-OEFA/DSAP | K6: 45028 | L6: =IF(A6="","",IF(K6="","",_xlfn.WORKDAY.INTL(K6,5,1,FERIADOS))) -> 45035 | M6: NO | P6: =IF(A6="","",IF(M6="NO","NO PRESENTÓ DESCARGOS",IF(N6="",IF(TODAY()<=L6,"EN PLAZO","VENCIDO"),IF(N6<=L6,"PRESENTADO EN PLAZO","PRESENTADO FUERA DE PLAZO")))) -> NO PRESENTÓ DESCARGOS | U6: SI | Y6: =IF(A6="","",IF(U6="SI","ELABORAR MC",IF(U6="NO","NO AMERITA ELABORAR MC","EN PROCESO"))) -> ELABORAR MC | Z6: =IF(A6="","",IF(AND(AR6=-1,Y6="ELABORAR MC"),"SIN REGISTRO DE ETAPAS",IF(AND(AR6=0,Y6="ELABORAR MC"),"EN PROCESO",IF(AND(AR6=1,Y6="ELABORAR MC",AB6=""),"EN ESPERA DE REGISTRO DE RESOLUCIÓN",IF(AND(AR6=1,Y6="ELABORAR MC",AB6<>""),"TERMINADO",IF(OR(Y6="NO AMERITA MC",Y6="EN PROCESO"),"","")))))) -> SIN REGISTRO DE ETAPAS | AA6: 0011-2023-DSAP-CAGR | AB6: 0126-2023-OEFA/DSAP | AC6: 45110 | AD6: 45111 | AE6: =IF(U6="","",IF(AD6="","",_xlfn.WORKDAY.INTL(AD6,7,1,FERIADOS))) -> 45120 | AF6: 11.25 | AG6: {=IF(A6="","",IF(AF6="","",AF6*INDEX(PARAMETROS!F$2:F1069,MATCH(YEAR(AC6),PARAMETROS!E$2:E1069,0),1)))} -> #N/A | AL6: INCUMPLIDO | AN6: 1421-2023-OEFA/DSAP | AO6: 45124 | AP6: 2023-I01-025671 | AQ6: =IF($A6="","",IF(OR(AB6="",AL6="EN EJECUCIÓN"),"EN PROCESO", IF(AE6="","INDICAR FECHA DE NOTIFICACIÓN",IF(AM6="","NO PAGÓ MULTA",IF(AM6="",IF(TODAY()<=AE6,"EN PLAZO","VENCIDO"),IF(AM6<=AE6,"PAGADO EN PLAZO","PAGADO FUERA DE PLAZO")))))) -> NO PAGÓ MULTA | AR6: {=IF(A6="","",IFERROR(INDEX('2) Etapas'!L$3:L923,MATCH(B6,'2) Etapas'!$A$4:$A923,0),1),-1))} -> -1 | AS6: =IF(A6="","",A6) -> 0016-2022-ACTA 0002-2-CAGR | AT6: =IF(A6="","",IF(AU6="","MULTA EN ELABORACIÓN", "MULTA IMPUESTA")) -> MULTA IMPUESTA | AU6: =IF(OR($A6="",$AB6="", $AC6=""),"", INDEX($AB$4:$AB925,MATCH(CONCATENATE($A6,$AV6),$A$4:$A925&$AC$4:$AC925,0),1)) -> 0126-2023-OEFA/DSAP | AV6: {=IF(OR($A6="",$AB6="", $AC6=""),"",MAXA(IF($A6=$A$4:$A923,$AC$4:$AC923)))} -> 45110
A7: 0184-2022-0117-2023-1-CAGR | B7: =IF(A7="","",IF(E7="","INDICAR NÚMERO DE PROYECTO",CONCATENATE("MULTA COERCITIVA - ",E7,"/",F7))) -> MULTA COERCITIVA - 3/CÓDIGO DE EXPEDIENTE INVÁLIDO | C7: PEÑA, AGUSTÍN | D7: =IF(A7="","",IF(AL7<>"","EN ETAPA DE COBRANZA",IF(AH7<>"","EN SEGUIMIENTO DE MULTA",IF(AB7<>"","EN IMPOISICIÓN DE MULTA",IF(Q7<>"","EN ETAPA DE ÁNALISIS DE DESCARGOS",IF(OR(P8="VENCIDO", P8="EN PLAZO"),"EN ETAPA DE DESCARGOS","EN ETAPA DE DESCARGOS")))))) -> EN ETAPA DE COBRANZA | E7: 3 | F7: {=IF($A7="","",IFERROR(INDEX(MA_INDIVIDUALES!C$2:C923, MATCH($A7,MA_INDIVIDUALES!$B$2:$B923,0),1),"CÓDIGO DE EXPEDIENTE INVÁLIDO"))} -> CÓDIGO DE EXPEDIENTE INVÁLIDO | G7: {=IF($A7="","",IFERROR(INDEX(MA_INDIVIDUALES!K$2:K923, MATCH($A7,MA_INDIVIDUALES!$B$2:$B923,0),1),"CÓDIGO DE EXPEDIENTE INVÁLIDO"))} -> CÓDIGO DE EXPEDIENTE INVÁLIDO | H7: {=IF($A7="","",IFERROR(INDEX(MA_INDIVIDUALES!L$2:L923, MATCH($A7,MA_INDIVIDUALES!$B$2:$B923,0),1),"CÓDIGO DE EXPEDIENTE INVÁLIDO"))} -> CÓDIGO DE EXPEDIENTE INVÁLIDO | I7: 0085-2023-DSAP-CAGR | J7: 1021-2023-OEFA/DSAP | K7: 45120 | L7: =IF(A7="","",IF(K7="","",_xlfn.WORKDAY.INTL(K7,5,1,FERIADOS))) -> 45127 | M7: NO | P7: =IF(A7="","",IF(M7="NO","NO PRESENTÓ DESCARGOS",IF(N7="",IF(TODAY()<=L7,"EN PLAZO","VENCIDO"),IF(N7<=L7,"PRESENTADO EN PLAZO","PRESENTADO FUERA DE PLAZO")))) -> NO PRESENTÓ DESCARGOS | U7: SI | Y7: =IF(A7="","",IF(U7="SI","ELABORAR MC",IF(U7="NO","NO AMERITA ELABORAR MC","EN PROCESO"))) -> ELABORAR MC | Z7: =IF(A7="","",IF(AND(AR7=-1,Y7="ELABORAR MC"),"SIN REGISTRO DE ETAPAS",IF(AND(AR7=0,Y7="ELABORAR MC"),"EN PROCESO",IF(AND(AR7=1,Y7="ELABORAR MC",AB7=""),"EN ESPERA DE REGISTRO DE RESOLUCIÓN",IF(AND(AR7=1,Y7="ELABORAR MC",AB7<>""),"TERMINADO",IF(OR(Y7="NO AMERITA MC",Y7="EN PROCESO"),"","")))))) -> SIN REGISTRO DE ETAPAS | AA7: 0085-2023-DSAP-CAGR | AB7: 0132-2023-OEFA/DSAP | AC7: 45148 | AD7: 45148 | AE7: =IF(U7="","",IF(AD7="","",_xlfn.WORKDAY.INTL(AD7,7,1,FERIADOS))) -> 45159 | AF7: 6.5625 | AG7: {=IF(A7="","",IF(AF7="","",AF7*INDEX(PARAMETROS!F$2:F1070,MATCH(YEAR(AC7),PARAMETROS!E$2:E1070,0),1)))} -> #N/A | AL7: INCUMPLIDO | AN7: 1810-2023-OEFA/DSAP | AO7: 45169 | AP7: 2023-I01-032037 | AQ7: =IF($A7="","",IF(OR(AB7="",AL7="EN EJECUCIÓN"),"EN PROCESO", IF(AE7="","INDICAR FECHA DE NOTIFICACIÓN",IF(AM7="","NO PAGÓ MULTA",IF(AM7="",IF(TODAY()<=AE7,"EN PLAZO","VENCIDO"),IF(AM7<=AE7,"PAGADO EN PLAZO","PAGADO FUERA DE PLAZO")))))) -> NO PAGÓ MULTA | AR7: {=IF(A7="","",IFERROR(INDEX('2) Etapas'!L$3:L923,MATCH(B7,'2) Etapas'!$A$4:$A923,0),1),-1))} -> -1 | AS7: =IF(A7="","",A7) -> 0184-2022-0117-2023-1-CAGR | AT7: =IF(A7="","",IF(AU7="","MULTA EN ELABORACIÓN", "MULTA IMPUESTA")) -> MULTA IMPUESTA | AU7: =IF(OR($A7="",$AB7="", $AC7=""),"", INDEX($AB$4:$AB926,MATCH(CONCATENATE($A7,$AV7),$A$4:$A926&$AC$4:$AC926,0),1)) -> 0022-2025-OEFA/DSAP | AV7: {=IF(OR($A7="",$AB7="", $AC7=""),"",MAXA(IF($A7=$A$4:$A923,$AC$4:$AC923)))} -> 45743
A8: 0101-2021-0008-2022-1-CAGR | B8: =IF(A8="","",IF(E8="","INDICAR NÚMERO DE PROYECTO",CONCATENATE("MULTA COERCITIVA - ",E8,"/",F8))) -> MULTA COERCITIVA - 4/CÓDIGO DE EXPEDIENTE INVÁLIDO | C8: RIMACHI, LUIS | D8: =IF(A8="","",IF(AL8<>"","EN ETAPA DE COBRANZA",IF(AH8<>"","EN SEGUIMIENTO DE MULTA",IF(AB8<>"","EN IMPOISICIÓN DE MULTA",IF(Q8<>"","EN ETAPA DE ÁNALISIS DE DESCARGOS",IF(OR(P9="VENCIDO", P9="EN PLAZO"),"EN ETAPA DE DESCARGOS","EN ETAPA DE DESCARGOS")))))) -> EN ETAPA DE COBRANZA | E8: 4 | F8: {=IF($A8="","",IFERROR(INDEX(MA_INDIVIDUALES!C$2:C923, MATCH($A8,MA_INDIVIDUALES!$B$2:$B923,0),1),"CÓDIGO DE EXPEDIENTE INVÁLIDO"))} -> CÓDIGO DE EXPEDIENTE INVÁLIDO | G8: {=IF($A8="","",IFERROR(INDEX(MA_INDIVIDUALES!K$2:K923, MATCH($A8,MA_INDIVIDUALES!$B$2:$B923,0),1),"CÓDIGO DE EXPEDIENTE INVÁLIDO"))} -> CÓDIGO DE EXPEDIENTE INVÁLIDO | H8: {=IF($A8="","",IFERROR(INDEX(MA_INDIVIDUALES!L$2:L923, MATCH($A8,MA_INDIVIDUALES!$B$2:$B923,0),1),"CÓDIGO DE EXPEDIENTE INVÁLIDO"))} -> CÓDIGO DE EXPEDIENTE INVÁLIDO | I8: 0101-2021-DSAP-CAGR | J8: 0565-2023-OEFA/DSAP | K8: 45117 | L8: =IF(A8="","",IF(K8="","",_xlfn.WORKDAY.INTL(K8,5,1,FERIADOS))) -> 45124 | M8: NO | P8: =IF(A8="","",IF(M8="NO","NO PRESENTÓ DESCARGOS",IF(N8="",IF(TODAY()<=L8,"EN PLAZO","VENCIDO"),IF(N8<=L8,"PRESENTADO EN PLAZO","PRESENTADO FUERA DE PLAZO")))) -> NO PRESENTÓ DESCARGOS | U8: SI | Y8: =IF(A8="","",IF(U8="SI","ELABORAR MC",IF(U8="NO","NO AMERITA ELABORAR MC","EN PROCESO"))) -> ELABORAR MC | Z8: =IF(A8="","",IF(AND(AR8=-1,Y8="ELABORAR MC"),"SIN REGISTRO DE ETAPAS",IF(AND(AR8=0,Y8="ELABORAR MC"),"EN PROCESO",IF(AND(AR8=1,Y8="ELABORAR MC",AB8=""),"EN ESPERA DE REGISTRO DE RESOLUCIÓN",IF(AND(AR8=1,Y8="ELABORAR MC",AB8<>""),"TERMINADO",IF(OR(Y8="NO AMERITA MC",Y8="EN PROCESO"),"","")))))) -> SIN REGISTRO DE ETAPAS | AA8: 0101-2021-DSAP-CAGR | AB8: 0133-2023-OEFA/DSAP | AC8: 45148 | AD8: 45148 | AE8: =IF(U8="","",IF(AD8="","",_xlfn.WORKDAY.INTL(AD8,7,1,FERIADOS))) -> 45159 | AF8: 5 | AG8: {=IF(A8="","",IF(AF8="","",AF8*INDEX(PARAMETROS!F$2:F1071,MATCH(YEAR(AC8),PARAMETROS!E$2:E1071,0),1)))} -> #N/A | AL8: INCUMPLIDO | AN8: 1810-2023-OEFA/DSAP | AO8: 45169 | AP8: 2023-I01-032037 | AQ8: =IF($A8="","",IF(OR(AB8="",AL8="EN EJECUCIÓN"),"EN PROCESO", IF(AE8="","INDICAR FECHA DE NOTIFICACIÓN",IF(AM8="","NO PAGÓ MULTA",IF(AM8="",IF(TODAY()<=AE8,"EN PLAZO","VENCIDO"),IF(AM8<=AE8,"PAGADO EN PLAZO","PAGADO FUERA DE PLAZO")))))) -> NO PAGÓ MULTA | AR8: {=IF(A8="","",IFERROR(INDEX('2) Etapas'!L$3:L923,MATCH(B8,'2) Etapas'!$A$4:$A923,0),1),-1))} -> -1 | AS8: =IF(A8="","",A8) -> 0101-2021-0008-2022-1-CAGR | AT8: =IF(A8="","",IF(AU8="","MULTA EN ELABORACIÓN", "MULTA IMPUESTA")) -> MULTA IMPUESTA | AU8: =IF(OR($A8="",$AB8="", $AC8=""),"", INDEX($AB$4:$AB927,MATCH(CONCATENATE($A8,$AV8),$A$4:$A927&$AC$4:$AC927,0),1)) -> 0133-2023-OEFA/DSAP | AV8: {=IF(OR($A8="",$AB8="", $AC8=""),"",MAXA(IF($A8=$A$4:$A923,$AC$4:$AC923)))} -> 45148
A9: 0223-2022-ACTA 0003-1-CAGR | B9: =IF(A9="","",IF(E9="","INDICAR NÚMERO DE PROYECTO",CONCATENATE("MULTA COERCITIVA - ",E9,"/",F9))) -> MULTA COERCITIVA - 5/CÓDIGO DE EXPEDIENTE INVÁLIDO | C9: PEÑA, AGUSTÍN | D9: =IF(A9="","",IF(AL9<>"","EN ETAPA DE COBRANZA",IF(AH9<>"","EN SEGUIMIENTO DE MULTA",IF(AB9<>"","EN IMPOISICIÓN DE MULTA",IF(Q9<>"","EN ETAPA DE ÁNALISIS DE DESCARGOS",IF(OR(P10="VENCIDO", P10="EN PLAZO"),"EN ETAPA DE DESCARGOS","EN ETAPA DE DESCARGOS")))))) -> EN ETAPA DE COBRANZA | E9: 5 | F9: {=IF($A9="","",IFERROR(INDEX(MA_INDIVIDUALES!C$2:C923, MATCH($A9,MA_INDIVIDUALES!$B$2:$B923,0),1),"CÓDIGO DE EXPEDIENTE INVÁLIDO"))} -> CÓDIGO DE EXPEDIENTE INVÁLIDO | G9: {=IF($A9="","",IFERROR(INDEX(MA_INDIVIDUALES!K$2:K923, MATCH($A9,MA_INDIVIDUALES!$B$2:$B923,0),1),"CÓDIGO DE EXPEDIENTE INVÁLIDO"))} -> CÓDIGO DE EXPEDIENTE INVÁLIDO | H9: {=IF($A9="","",IFERROR(INDEX(MA_INDIVIDUALES!L$2:L923, MATCH($A9,MA_INDIVIDUALES!$B$2:$B923,0),1),"CÓDIGO DE EXPEDIENTE INVÁLIDO"))} -> CÓDIGO DE EXPEDIENTE INVÁLIDO | I9: 0223-2022-DSAP-CAGR | J9: 0316-2023-OEFA/DSAP | K9: 45050 | L9: =IF(A9="","",IF(K9="","",_xlfn.WORKDAY.INTL(K9,5,1,FERIADOS))) -> 45057 | M9: NO | P9: =IF(A9="","",IF(M9="NO","NO PRESENTÓ DESCARGOS",IF(N9="",IF(TODAY()<=L9,"EN PLAZO","VENCIDO"),IF(N9<=L9,"PRESENTADO EN PLAZO","PRESENTADO FUERA DE PLAZO")))) -> NO PRESENTÓ DESCARGOS | U9: SI | Y9: =IF(A9="","",IF(U9="SI","ELABORAR MC",IF(U9="NO","NO AMERITA ELABORAR MC","EN PROCESO"))) -> ELABORAR MC | Z9: =IF(A9="","",IF(AND(AR9=-1,Y9="ELABORAR MC"),"SIN REGISTRO DE ETAPAS",IF(AND(AR9=0,Y9="ELABORAR MC"),"EN PROCESO",IF(AND(AR9=1,Y9="ELABORAR MC",AB9=""),"EN ESPERA DE REGISTRO DE RESOLUCIÓN",IF(AND(AR9=1,Y9="ELABORAR MC",AB9<>""),"TERMINADO",IF(OR(Y9="NO AMERITA MC",Y9="EN PROCESO"),"","")))))) -> SIN REGISTRO DE ETAPAS | AA9: 0223-2022-DSAP-CAGR | AB9: 0134-2023-OEFA/DSAP | AC9: 45152 | AD9: 45152 | AE9: =IF(U9="","",IF(AD9="","",_xlfn.WORKDAY.INTL(AD9,7,1,FERIADOS))) -> 45161 | AF9: 3.75 | AG9: {=IF(A9="","",IF(AF9="","",AF9*INDEX(PARAMETROS!F$2:F1072,MATCH(YEAR(AC9),PARAMETROS!E$2:E1072,0),1)))} -> #N/A | AL9: INCUMPLIDO | AN9: 1810-2023-OEFA/DSAP | AO9: 45169 | AP9: 2023-I01-032037 | AQ9: =IF($A9="","",IF(OR(AB9="",AL9="EN EJECUCIÓN"),"EN PROCESO", IF(AE9="","INDICAR FECHA DE NOTIFICACIÓN",IF(AM9="","NO PAGÓ MULTA",IF(AM9="",IF(TODAY()<=AE9,"EN PLAZO","VENCIDO"),IF(AM9<=AE9,"PAGADO EN PLAZO","PAGADO FUERA DE PLAZO")))))) -> NO PAGÓ MULTA | AR9: {=IF(A9="","",IFERROR(INDEX('2) Etapas'!L$3:L923,MATCH(B9,'2) Etapas'!$A$4:$A923,0),1),-1))} -> -1 | AS9: =IF(A9="","",A9) -> 0223-2022-ACTA 0003-1-CAGR | AT9: =IF(A9="","",IF(AU9="","MULTA EN ELABORACIÓN", "MULTA IMPUESTA")) -> MULTA IMPUESTA | AU9: =IF(OR($A9="",$AB9="", $AC9=""),"", INDEX($AB$4:$AB928,MATCH(CONCATENATE($A9,$AV9),$A$4:$A928&$AC$4:$AC928,0),1)) -> 00009-2026-OEFA/DSAP | AV9: {=IF(OR($A9="",$AB9="", $AC9=""),"",MAXA(IF($A9=$A$4:$A923,$AC$4:$AC923)))} -> 46080
A10: 0223-2022-ACTA 0003-3-CAGR | B10: =IF(A10="","",IF(E10="","INDICAR NÚMERO DE PROYECTO",CONCATENATE("MULTA COERCITIVA - ",E10,"/",F10))) -> MULTA COERCITIVA - 5/CÓDIGO DE EXPEDIENTE INVÁLIDO | C10: PEÑA, AGUSTÍN | D10: =IF(A10="","",IF(AL10<>"","EN ETAPA DE COBRANZA",IF(AH10<>"","EN SEGUIMIENTO DE MULTA",IF(AB10<>"","EN IMPOISICIÓN DE MULTA",IF(Q10<>"","EN ETAPA DE ÁNALISIS DE DESCARGOS",IF(OR(P11="VENCIDO", P11="EN PLAZO"),"EN ETAPA DE DESCARGOS","EN ETAPA DE DESCARGOS")))))) -> EN ETAPA DE COBRANZA | E10: 5 | F10: {=IF($A10="","",IFERROR(INDEX(MA_INDIVIDUALES!C$2:C923, MATCH($A10,MA_INDIVIDUALES!$B$2:$B923,0),1),"CÓDIGO DE EXPEDIENTE INVÁLIDO"))} -> CÓDIGO DE EXPEDIENTE INVÁLIDO | G10: {=IF($A10="","",IFERROR(INDEX(MA_INDIVIDUALES!K$2:K923, MATCH($A10,MA_INDIVIDUALES!$B$2:$B923,0),1),"CÓDIGO DE EXPEDIENTE INVÁLIDO"))} -> CÓDIGO DE EXPEDIENTE INVÁLIDO | H10: {=IF($A10="","",IFERROR(INDEX(MA_INDIVIDUALES!L$2:L923, MATCH($A10,MA_INDIVIDUALES!$B$2:$B923,0),1),"CÓDIGO DE EXPEDIENTE INVÁLIDO"))} -> CÓDIGO DE EXPEDIENTE INVÁLIDO | I10: 0223-2022-DSAP-CAGR | J10: 0316-2023-OEFA/DSAP | K10: 45050 | L10: =IF(A10="","",IF(K10="","",_xlfn.WORKDAY.INTL(K10,5,1,FERIADOS))) -> 45057 | M10: NO | P10: =IF(A10="","",IF(M10="NO","NO PRESENTÓ DESCARGOS",IF(N10="",IF(TODAY()<=L10,"EN PLAZO","VENCIDO"),IF(N10<=L10,"PRESENTADO EN PLAZO","PRESENTADO FUERA DE PLAZO")))) -> NO PRESENTÓ DESCARGOS | U10: SI | Y10: =IF(A10="","",IF(U10="SI","ELABORAR MC",IF(U10="NO","NO AMERITA ELABORAR MC","EN PROCESO"))) -> ELABORAR MC | Z10: =IF(A10="","",IF(AND(AR10=-1,Y10="ELABORAR MC"),"SIN REGISTRO DE ETAPAS",IF(AND(AR10=0,Y10="ELABORAR MC"),"EN PROCESO",IF(AND(AR10=1,Y10="ELABORAR MC",AB10=""),"EN ESPERA DE REGISTRO DE RESOLUCIÓN",IF(AND(AR10=1,Y10="ELABORAR MC",AB10<>""),"TERMINADO",IF(OR(Y10="NO AMERITA MC",Y10="EN PROCESO"),"","")))))) -> SIN REGISTRO DE ETAPAS | AA10: 0223-2022-DSAP-CAGR | AB10: 0134-2023-OEFA/DSAP | AC10: 45152 | AD10: 45152 | AE10: =IF(U10="","",IF(AD10="","",_xlfn.WORKDAY.INTL(AD10,7,1,FERIADOS))) -> 45161 | AF10: 3.75 | AG10: {=IF(A10="","",IF(AF10="","",AF10*INDEX(PARAMETROS!F$2:F1073,MATCH(YEAR(AC10),PARAMETROS!E$2:E1073,0),1)))} -> #N/A | AL10: INCUMPLIDO | AN10: 1810-2023-OEFA/DSAP | AO10: 45169 | AP10: 2023-I01-032037 | AQ10: =IF($A10="","",IF(OR(AB10="",AL10="EN EJECUCIÓN"),"EN PROCESO", IF(AE10="","INDICAR FECHA DE NOTIFICACIÓN",IF(AM10="","NO PAGÓ MULTA",IF(AM10="",IF(TODAY()<=AE10,"EN PLAZO","VENCIDO"),IF(AM10<=AE10,"PAGADO EN PLAZO","PAGADO FUERA DE PLAZO")))))) -> NO PAGÓ MULTA | AR10: {=IF(A10="","",IFERROR(INDEX('2) Etapas'!L$3:L923,MATCH(B10,'2) Etapas'!$A$4:$A923,0),1),-1))} -> -1 | AS10: =IF(A10="","",A10) -> 0223-2022-ACTA 0003-3-CAGR | AT10: =IF(A10="","",IF(AU10="","MULTA EN ELABORACIÓN", "MULTA IMPUESTA")) -> MULTA IMPUESTA | AU10: =IF(OR($A10="",$AB10="", $AC10=""),"", INDEX($AB$4:$AB929,MATCH(CONCATENATE($A10,$AV10),$A$4:$A929&$AC$4:$AC929,0),1)) -> 00009-2026-OEFA/DSAP | AV10: {=IF(OR($A10="",$AB10="", $AC10=""),"",MAXA(IF($A10=$A$4:$A923,$AC$4:$AC923)))} -> 46080
A11: 0040-2023-0149-2023-1-CAGR | B11: =IF(A11="","",IF(E11="","INDICAR NÚMERO DE PROYECTO",CONCATENATE("MULTA COERCITIVA - ",E11,"/",F11))) -> MULTA COERCITIVA - 6/CÓDIGO DE EXPEDIENTE INVÁLIDO | C11: PEÑA, AGUSTÍN | D11: =IF(A11="","",IF(AL11<>"","EN ETAPA DE COBRANZA",IF(AH11<>"","EN SEGUIMIENTO DE MULTA",IF(AB11<>"","EN IMPOISICIÓN DE MULTA",IF(Q11<>"","EN ETAPA DE ÁNALISIS DE DESCARGOS",IF(OR(P12="VENCIDO", P12="EN PLAZO"),"EN ETAPA DE DESCARGOS","EN ETAPA DE DESCARGOS")))))) -> EN ETAPA DE COBRANZA | E11: 6 | F11: {=IF($A11="","",IFERROR(INDEX(MA_INDIVIDUALES!C$2:C923, MATCH($A11,MA_INDIVIDUALES!$B$2:$B923,0),1),"CÓDIGO DE EXPEDIENTE INVÁLIDO"))} -> CÓDIGO DE EXPEDIENTE INVÁLIDO | G11: {=IF($A11="","",IFERROR(INDEX(MA_INDIVIDUALES!K$2:K923, MATCH($A11,MA_INDIVIDUALES!$B$2:$B923,0),1),"CÓDIGO DE EXPEDIENTE INVÁLIDO"))} -> CÓDIGO DE EXPEDIENTE INVÁLIDO | H11: {=IF($A11="","",IFERROR(INDEX(MA_INDIVIDUALES!L$2:L923, MATCH($A11,MA_INDIVIDUALES!$B$2:$B923,0),1),"CÓDIGO DE EXPEDIENTE INVÁLIDO"))} -> CÓDIGO DE EXPEDIENTE INVÁLIDO | I11: 0150-2024-DSAP-CAGR | J11: 1723-2024-OEFA/DSAP | K11: 45579 | L11: =IF(A11="","",IF(K11="","",_xlfn.WORKDAY.INTL(K11,5,1,FERIADOS))) -> 45586 | M11: NO | P11: =IF(A11="","",IF(M11="NO","NO PRESENTÓ DESCARGOS",IF(N11="",IF(TODAY()<=L11,"EN PLAZO","VENCIDO"),IF(N11<=L11,"PRESENTADO EN PLAZO","PRESENTADO FUERA DE PLAZO")))) -> NO PRESENTÓ DESCARGOS | U11: SI | Y11: =IF(A11="","",IF(U11="SI","ELABORAR MC",IF(U11="NO","NO AMERITA ELABORAR MC","EN PROCESO"))) -> ELABORAR MC | Z11: =IF(A11="","",IF(AND(AR11=-1,Y11="ELABORAR MC"),"SIN REGISTRO DE ETAPAS",IF(AND(AR11=0,Y11="ELABORAR MC"),"EN PROCESO",IF(AND(AR11=1,Y11="ELABORAR MC",AB11=""),"EN ESPERA DE REGISTRO DE RESOLUCIÓN",IF(AND(AR11=1,Y11="ELABORAR MC",AB11<>""),"TERMINADO",IF(OR(Y11="NO AMERITA MC",Y11="EN PROCESO"),"","")))))) -> SIN REGISTRO DE ETAPAS | AA11: 0150-2024-DSAP-CAGR | AB11: 0008-2025-OEFA/DSAP | AC11: 45687 | AD11: 45688 | AE11: =IF(U11="","",IF(AD11="","",_xlfn.WORKDAY.INTL(AD11,7,1,FERIADOS))) -> 45699 | AF11: 20.25 | AG11: {=IF(A11="","",IF(AF11="","",AF11*INDEX(PARAMETROS!F$2:F1074,MATCH(YEAR(AC11),PARAMETROS!E$2:E1074,0),1)))} -> #N/A | AL11: INCUMPLIDO | AN11: 0754-2025-OEFA/DSAP | AO11: 45734 | AP11: 2025-I01-012041 | AQ11: =IF($A11="","",IF(OR(AB11="",AL11="EN EJECUCIÓN"),"EN PROCESO", IF(AE11="","INDICAR FECHA DE NOTIFICACIÓN",IF(AM11="","NO PAGÓ MULTA",IF(AM11="",IF(TODAY()<=AE11,"EN PLAZO","VENCIDO"),IF(AM11<=AE11,"PAGADO EN PLAZO","PAGADO FUERA DE PLAZO")))))) -> NO PAGÓ MULTA | AR11: {=IF(A11="","",IFERROR(INDEX('2) Etapas'!L$3:L923,MATCH(B11,'2) Etapas'!$A$4:$A923,0),1),-1))} -> -1 | AS11: =IF(A11="","",A11) -> 0040-2023-0149-2023-1-CAGR | AT11: =IF(A11="","",IF(AU11="","MULTA EN ELABORACIÓN", "MULTA IMPUESTA")) -> MULTA IMPUESTA | AU11: =IF(OR($A11="",$AB11="", $AC11=""),"", INDEX($AB$4:$AB930,MATCH(CONCATENATE($A11,$AV11),$A$4:$A930&$AC$4:$AC930,0),1)) -> 0008-2025-OEFA/DSAP | AV11: {=IF(OR($A11="",$AB11="", $AC11=""),"",MAXA(IF($A11=$A$4:$A923,$AC$4:$AC923)))} -> 45687
A12: 0184-2022-0117-2023-1-CAGR | B12: =IF(A12="","",IF(E12="","INDICAR NÚMERO DE PROYECTO",CONCATENATE("MULTA COERCITIVA - ",E12,"/",F12))) -> MULTA COERCITIVA - 7/CÓDIGO DE EXPEDIENTE INVÁLIDO | C12: PEÑA, AGUSTÍN | D12: =IF(A12="","",IF(AL12<>"","EN ETAPA DE COBRANZA",IF(AH12<>"","EN SEGUIMIENTO DE MULTA",IF(AB12<>"","EN IMPOISICIÓN DE MULTA",IF(Q12<>"","EN ETAPA DE ÁNALISIS DE DESCARGOS",IF(OR(P13="VENCIDO", P13="EN PLAZO"),"EN ETAPA DE DESCARGOS","EN ETAPA DE DESCARGOS")))))) -> EN ETAPA DE COBRANZA | E12: 7 | F12: {=IF($A12="","",IFERROR(INDEX(MA_INDIVIDUALES!C$2:C923, MATCH($A12,MA_INDIVIDUALES!$B$2:$B923,0),1),"CÓDIGO DE EXPEDIENTE INVÁLIDO"))} -> CÓDIGO DE EXPEDIENTE INVÁLIDO | G12: {=IF($A12="","",IFERROR(INDEX(MA_INDIVIDUALES!K$2:K923, MATCH($A12,MA_INDIVIDUALES!$B$2:$B923,0),1),"CÓDIGO DE EXPEDIENTE INVÁLIDO"))} -> CÓDIGO DE EXPEDIENTE INVÁLIDO | H12: {=IF($A12="","",IFERROR(INDEX(MA_INDIVIDUALES!L$2:L923, MATCH($A12,MA_INDIVIDUALES!$B$2:$B923,0),1),"CÓDIGO DE EXPEDIENTE INVÁLIDO"))} -> CÓDIGO DE EXPEDIENTE INVÁLIDO | I12: 0233-2024-DSAP-CAGR | J12: 0103-2025-OEFA/DSAP | K12: 45684 | L12: =IF(A12="","",IF(K12="","",_xlfn.WORKDAY.INTL(K12,5,1,FERIADOS))) -> 45691 | M12: SI | N12: 45768 | O12: 2025-E01-053756 | P12: =IF(A12="","",IF(M12="NO","NO PRESENTÓ DESCARGOS",IF(N12="",IF(TODAY()<=L12,"EN PLAZO","VENCIDO"),IF(N12<=L12,"PRESENTADO EN PLAZO","PRESENTADO FUERA DE PLAZO")))) -> PRESENTADO FUERA DE PLAZO | Q12: 45772 | R12: NO | T12: 45810 | U12: SI | Y12: =IF(A12="","",IF(U12="SI","ELABORAR MC",IF(U12="NO","NO AMERITA ELABORAR MC","EN PROCESO"))) -> ELABORAR MC | Z12: =IF(A12="","",IF(AND(AR12=-1,Y12="ELABORAR MC"),"SIN REGISTRO DE ETAPAS",IF(AND(AR12=0,Y12="ELABORAR MC"),"EN PROCESO",IF(AND(AR12=1,Y12="ELABORAR MC",AB12=""),"EN ESPERA DE REGISTRO DE RESOLUCIÓN",IF(AND(AR12=1,Y12="ELABORAR MC",AB12<>""),"TERMINADO",IF(OR(Y12="NO AMERITA MC",Y12="EN PROCESO"),"","")))))) -> SIN REGISTRO DE ETAPAS | AA12: 0233-2024-DSAP-CAGR | AB12: 0022-2025-OEFA/DSAP | AC12: 45743 | AD12: 45744 | AE12: =IF(U12="","",IF(AD12="","",_xlfn.WORKDAY.INTL(AD12,7,1,FERIADOS))) -> 45755 | AF12: 20.25 | AG12: {=IF(A12="","",IF(AF12="","",AF12*INDEX(PARAMETROS!F$2:F1075,MATCH(YEAR(AC12),PARAMETROS!E$2:E1075,0),1)))} -> #N/A | AL12: INCUMPLIDO | AN12: 2558-2025-OEFA/DSAP | AO12: 45915 | AP12: 2025-I01-040793 | AQ12: =IF($A12="","",IF(OR(AB12="",AL12="EN EJECUCIÓN"),"EN PROCESO", IF(AE12="","INDICAR FECHA DE NOTIFICACIÓN",IF(AM12="","NO PAGÓ MULTA",IF(AM12="",IF(TODAY()<=AE12,"EN PLAZO","VENCIDO"),IF(AM12<=AE12,"PAGADO EN PLAZO","PAGADO FUERA DE PLAZO")))))) -> NO PAGÓ MULTA | AR12: {=IF(A12="","",IFERROR(INDEX('2) Etapas'!L$3:L923,MATCH(B12,'2) Etapas'!$A$4:$A923,0),1),-1))} -> -1 | AS12: =IF(A12="","",A12) -> 0184-2022-0117-2023-1-CAGR | AT12: =IF(A12="","",IF(AU12="","MULTA EN ELABORACIÓN", "MULTA IMPUESTA")) -> MULTA IMPUESTA | AU12: =IF(OR($A12="",$AB12="", $AC12=""),"", INDEX($AB$4:$AB931,MATCH(CONCATENATE($A12,$AV12),$A$4:$A931&$AC$4:$AC931,0),1)) -> 0022-2025-OEFA/DSAP | AV12: {=IF(OR($A12="",$AB12="", $AC12=""),"",MAXA(IF($A12=$A$4:$A923,$AC$4:$AC923)))} -> 45743
A13: 0184-2024-0019-2025-1-CAGR | B13: =IF(A13="","",IF(E13="","INDICAR NÚMERO DE PROYECTO",CONCATENATE("MULTA COERCITIVA - ",E13,"/",F13))) -> MULTA COERCITIVA - 8/CÓDIGO DE EXPEDIENTE INVÁLIDO | C13: CORCUERA, ALDO | D13: =IF(A13="","",IF(AL13<>"","EN ETAPA DE COBRANZA",IF(AH13<>"","EN SEGUIMIENTO DE MULTA",IF(AB13<>"","EN IMPOISICIÓN DE MULTA",IF(Q13<>"","EN ETAPA DE ÁNALISIS DE DESCARGOS",IF(OR(P14="VENCIDO", P14="EN PLAZO"),"EN ETAPA DE DESCARGOS","EN ETAPA DE DESCARGOS")))))) -> EN ETAPA DE COBRANZA | E13: 8 | F13: {=IF($A13="","",IFERROR(INDEX(MA_INDIVIDUALES!C$2:C923, MATCH($A13,MA_INDIVIDUALES!$B$2:$B923,0),1),"CÓDIGO DE EXPEDIENTE INVÁLIDO"))} -> CÓDIGO DE EXPEDIENTE INVÁLIDO | G13: {=IF($A13="","",IFERROR(INDEX(MA_INDIVIDUALES!K$2:K923, MATCH($A13,MA_INDIVIDUALES!$B$2:$B923,0),1),"CÓDIGO DE EXPEDIENTE INVÁLIDO"))} -> CÓDIGO DE EXPEDIENTE INVÁLIDO | H13: {=IF($A13="","",IFERROR(INDEX(MA_INDIVIDUALES!L$2:L923, MATCH($A13,MA_INDIVIDUALES!$B$2:$B923,0),1),"CÓDIGO DE EXPEDIENTE INVÁLIDO"))} -> CÓDIGO DE EXPEDIENTE INVÁLIDO | I13: 0180-2025-DSAP-CAGR | J13: 1664-2025-OEFA/DSAP | K13: 46007 | L13: =IF(A13="","",IF(K13="","",_xlfn.WORKDAY.INTL(K13,5,1,FERIADOS))) -> 46014 | M13: NO | P13: =IF(A13="","",IF(M13="NO","NO PRESENTÓ DESCARGOS",IF(N13="",IF(TODAY()<=L13,"EN PLAZO","VENCIDO"),IF(N13<=L13,"PRESENTADO EN PLAZO","PRESENTADO FUERA DE PLAZO")))) -> NO PRESENTÓ DESCARGOS | U13: SI | Y13: =IF(A13="","",IF(U13="SI","ELABORAR MC",IF(U13="NO","NO AMERITA ELABORAR MC","EN PROCESO"))) -> ELABORAR MC | Z13: =IF(A13="","",IF(AND(AR13=-1,Y13="ELABORAR MC"),"SIN REGISTRO DE ETAPAS",IF(AND(AR13=0,Y13="ELABORAR MC"),"EN PROCESO",IF(AND(AR13=1,Y13="ELABORAR MC",AB13=""),"EN ESPERA DE REGISTRO DE RESOLUCIÓN",IF(AND(AR13=1,Y13="ELABORAR MC",AB13<>""),"TERMINADO",IF(OR(Y13="NO AMERITA MC",Y13="EN PROCESO"),"","")))))) -> SIN REGISTRO DE ETAPAS | AA13: 0180-2025-DSAP-CAGR | AB13: 0004-2026-OEFA/DSAP | AC13: 46044 | AD13: 46044 | AE13: =IF(U13="","",IF(AD13="","",_xlfn.WORKDAY.INTL(AD13,7,1,FERIADOS))) -> 46055 | AF13: 4.68 | AG13: {=IF(A13="","",IF(AF13="","",AF13*INDEX(PARAMETROS!F$2:F1076,MATCH(YEAR(AC13),PARAMETROS!E$2:E1076,0),1)))} -> #N/A | AL13: INCUMPLIDO | AN13: 00337-2026-OEFA/DSAP | AO13: 46073 | AP13: 2026-I01-006274 | AQ13: =IF($A13="","",IF(OR(AB13="",AL13="EN EJECUCIÓN"),"EN PROCESO", IF(AE13="","INDICAR FECHA DE NOTIFICACIÓN",IF(AM13="","NO PAGÓ MULTA",IF(AM13="",IF(TODAY()<=AE13,"EN PLAZO","VENCIDO"),IF(AM13<=AE13,"PAGADO EN PLAZO","PAGADO FUERA DE PLAZO")))))) -> NO PAGÓ MULTA | AR13: {=IF(A13="","",IFERROR(INDEX('2) Etapas'!L$3:L923,MATCH(B13,'2) Etapas'!$A$4:$A923,0),1),-1))} -> -1 | AS13: =IF(A13="","",A13) -> 0184-2024-0019-2025-1-CAGR | AT13: =IF(A13="","",IF(AU13="","MULTA EN ELABORACIÓN", "MULTA IMPUESTA")) -> MULTA IMPUESTA | AU13: =IF(OR($A13="",$AB13="", $AC13=""),"", INDEX($AB$4:$AB932,MATCH(CONCATENATE($A13,$AV13),$A$4:$A932&$AC$4:$AC932,0),1)) -> 0016-2026-OEFA/DSAP | AV13: {=IF(OR($A13="",$AB13="", $AC13=""),"",MAXA(IF($A13=$A$4:$A923,$AC$4:$AC923)))} -> 46203
A14: 0223-2022-ACTA 0003-1-CAGR | B14: =IF(A14="","",IF(E14="","INDICAR NÚMERO DE PROYECTO",CONCATENATE("MULTA COERCITIVA - ",E14,"/",F14))) -> MULTA COERCITIVA - 9/CÓDIGO DE EXPEDIENTE INVÁLIDO | C14: PEÑA, AGUSTÍN | D14: =IF(A14="","",IF(AL14<>"","EN ETAPA DE COBRANZA",IF(AH14<>"","EN SEGUIMIENTO DE MULTA",IF(AB14<>"","EN IMPOISICIÓN DE MULTA",IF(Q14<>"","EN ETAPA DE ÁNALISIS DE DESCARGOS",IF(OR(P15="VENCIDO", P15="EN PLAZO"),"EN ETAPA DE DESCARGOS","EN ETAPA DE DESCARGOS")))))) -> EN ETAPA DE COBRANZA | E14: 9 | F14: {=IF($A14="","",IFERROR(INDEX(MA_INDIVIDUALES!C$2:C923, MATCH($A14,MA_INDIVIDUALES!$B$2:$B923,0),1),"CÓDIGO DE EXPEDIENTE INVÁLIDO"))} -> CÓDIGO DE EXPEDIENTE INVÁLIDO | G14: {=IF($A14="","",IFERROR(INDEX(MA_INDIVIDUALES!K$2:K923, MATCH($A14,MA_INDIVIDUALES!$B$2:$B923,0),1),"CÓDIGO DE EXPEDIENTE INVÁLIDO"))} -> CÓDIGO DE EXPEDIENTE INVÁLIDO | H14: {=IF($A14="","",IFERROR(INDEX(MA_INDIVIDUALES!L$2:L923, MATCH($A14,MA_INDIVIDUALES!$B$2:$B923,0),1),"CÓDIGO DE EXPEDIENTE INVÁLIDO"))} -> CÓDIGO DE EXPEDIENTE INVÁLIDO | I14: 0218-2024-DSAP-CAGR | J14: 00078-2025-OEFA/DSAP | K14: 45684 | L14: =IF(A14="","",IF(K14="","",_xlfn.WORKDAY.INTL(K14,5,1,FERIADOS))) -> 45691 | M14: NO | P14: =IF(A14="","",IF(M14="NO","NO PRESENTÓ DESCARGOS",IF(N14="",IF(TODAY()<=L14,"EN PLAZO","VENCIDO"),IF(N14<=L14,"PRESENTADO EN PLAZO","PRESENTADO FUERA DE PLAZO")))) -> NO PRESENTÓ DESCARGOS | U14: SI | Y14: =IF(A14="","",IF(U14="SI","ELABORAR MC",IF(U14="NO","NO AMERITA ELABORAR MC","EN PROCESO"))) -> ELABORAR MC | Z14: =IF(A14="","",IF(AND(AR14=-1,Y14="ELABORAR MC"),"SIN REGISTRO DE ETAPAS",IF(AND(AR14=0,Y14="ELABORAR MC"),"EN PROCESO",IF(AND(AR14=1,Y14="ELABORAR MC",AB14=""),"EN ESPERA DE REGISTRO DE RESOLUCIÓN",IF(AND(AR14=1,Y14="ELABORAR MC",AB14<>""),"TERMINADO",IF(OR(Y14="NO AMERITA MC",Y14="EN PROCESO"),"","")))))) -> SIN REGISTRO DE ETAPAS | AA14: 0218-2024-DSAP-CAGR | AB14: 00009-2026-OEFA/DSAP | AC14: 46080 | AD14: 46080 | AE14: =IF(U14="","",IF(AD14="","",_xlfn.WORKDAY.INTL(AD14,7,1,FERIADOS))) -> 46091 | AF14: 12.96 | AG14: {=IF(A14="","",IF(AF14="","",AF14*INDEX(PARAMETROS!F$2:F1077,MATCH(YEAR(AC14),PARAMETROS!E$2:E1077,0),1)))} -> #N/A | AL14: INCUMPLIDO | AQ14: =IF($A14="","",IF(OR(AB14="",AL14="EN EJECUCIÓN"),"EN PROCESO", IF(AE14="","INDICAR FECHA DE NOTIFICACIÓN",IF(AM14="","NO PAGÓ MULTA",IF(AM14="",IF(TODAY()<=AE14,"EN PLAZO","VENCIDO"),IF(AM14<=AE14,"PAGADO EN PLAZO","PAGADO FUERA DE PLAZO")))))) -> NO PAGÓ MULTA | AR14: {=IF(A14="","",IFERROR(INDEX('2) Etapas'!L$3:L923,MATCH(B14,'2) Etapas'!$A$4:$A923,0),1),-1))} -> -1 | AS14: =IF(A14="","",A14) -> 0223-2022-ACTA 0003-1-CAGR | AT14: =IF(A14="","",IF(AU14="","MULTA EN ELABORACIÓN", "MULTA IMPUESTA")) -> MULTA IMPUESTA | AU14: =IF(OR($A14="",$AB14="", $AC14=""),"", INDEX($AB$4:$AB933,MATCH(CONCATENATE($A14,$AV14),$A$4:$A933&$AC$4:$AC933,0),1)) -> 00009-2026-OEFA/DSAP | AV14: {=IF(OR($A14="",$AB14="", $AC14=""),"",MAXA(IF($A14=$A$4:$A923,$AC$4:$AC923)))} -> 46080
A15: 0223-2022-ACTA 0003-2-CAGR | B15: =IF(A15="","",IF(E15="","INDICAR NÚMERO DE PROYECTO",CONCATENATE("MULTA COERCITIVA - ",E15,"/",F15))) -> MULTA COERCITIVA - 9/CÓDIGO DE EXPEDIENTE INVÁLIDO | C15: PEÑA, AGUSTÍN | D15: =IF(A15="","",IF(AL15<>"","EN ETAPA DE COBRANZA",IF(AH15<>"","EN SEGUIMIENTO DE MULTA",IF(AB15<>"","EN IMPOISICIÓN DE MULTA",IF(Q15<>"","EN ETAPA DE ÁNALISIS DE DESCARGOS",IF(OR(P16="VENCIDO", P16="EN PLAZO"),"EN ETAPA DE DESCARGOS","EN ETAPA DE DESCARGOS")))))) -> EN ETAPA DE COBRANZA | E15: 9 | F15: {=IF($A15="","",IFERROR(INDEX(MA_INDIVIDUALES!C$2:C923, MATCH($A15,MA_INDIVIDUALES!$B$2:$B923,0),1),"CÓDIGO DE EXPEDIENTE INVÁLIDO"))} -> CÓDIGO DE EXPEDIENTE INVÁLIDO | G15: {=IF($A15="","",IFERROR(INDEX(MA_INDIVIDUALES!K$2:K923, MATCH($A15,MA_INDIVIDUALES!$B$2:$B923,0),1),"CÓDIGO DE EXPEDIENTE INVÁLIDO"))} -> CÓDIGO DE EXPEDIENTE INVÁLIDO | H15: {=IF($A15="","",IFERROR(INDEX(MA_INDIVIDUALES!L$2:L923, MATCH($A15,MA_INDIVIDUALES!$B$2:$B923,0),1),"CÓDIGO DE EXPEDIENTE INVÁLIDO"))} -> CÓDIGO DE EXPEDIENTE INVÁLIDO | I15: 0218-2024-DSAP-CAGR | J15: 00078-2025-OEFA/DSAP | K15: 45684 | L15: =IF(A15="","",IF(K15="","",_xlfn.WORKDAY.INTL(K15,5,1,FERIADOS))) -> 45691 | M15: NO | P15: =IF(A15="","",IF(M15="NO","NO PRESENTÓ DESCARGOS",IF(N15="",IF(TODAY()<=L15,"EN PLAZO","VENCIDO"),IF(N15<=L15,"PRESENTADO EN PLAZO","PRESENTADO FUERA DE PLAZO")))) -> NO PRESENTÓ DESCARGOS | U15: SI | Y15: =IF(A15="","",IF(U15="SI","ELABORAR MC",IF(U15="NO","NO AMERITA ELABORAR MC","EN PROCESO"))) -> ELABORAR MC | Z15: =IF(A15="","",IF(AND(AR15=-1,Y15="ELABORAR MC"),"SIN REGISTRO DE ETAPAS",IF(AND(AR15=0,Y15="ELABORAR MC"),"EN PROCESO",IF(AND(AR15=1,Y15="ELABORAR MC",AB15=""),"EN ESPERA DE REGISTRO DE RESOLUCIÓN",IF(AND(AR15=1,Y15="ELABORAR MC",AB15<>""),"TERMINADO",IF(OR(Y15="NO AMERITA MC",Y15="EN PROCESO"),"","")))))) -> SIN REGISTRO DE ETAPAS | AA15: 0218-2024-DSAP-CAGR | AB15: 00009-2026-OEFA/DSAP | AC15: 46080 | AD15: 46080 | AE15: =IF(U15="","",IF(AD15="","",_xlfn.WORKDAY.INTL(AD15,7,1,FERIADOS))) -> 46091 | AF15: 3.2 | AG15: {=IF(A15="","",IF(AF15="","",AF15*INDEX(PARAMETROS!F$2:F1078,MATCH(YEAR(AC15),PARAMETROS!E$2:E1078,0),1)))} -> #N/A | AL15: INCUMPLIDO | AQ15: =IF($A15="","",IF(OR(AB15="",AL15="EN EJECUCIÓN"),"EN PROCESO", IF(AE15="","INDICAR FECHA DE NOTIFICACIÓN",IF(AM15="","NO PAGÓ MULTA",IF(AM15="",IF(TODAY()<=AE15,"EN PLAZO","VENCIDO"),IF(AM15<=AE15,"PAGADO EN PLAZO","PAGADO FUERA DE PLAZO")))))) -> NO PAGÓ MULTA | AR15: {=IF(A15="","",IFERROR(INDEX('2) Etapas'!L$3:L923,MATCH(B15,'2) Etapas'!$A$4:$A923,0),1),-1))} -> -1 | AS15: =IF(A15="","",A15) -> 0223-2022-ACTA 0003-2-CAGR | AT15: =IF(A15="","",IF(AU15="","MULTA EN ELABORACIÓN", "MULTA IMPUESTA")) -> MULTA IMPUESTA | AU15: =IF(OR($A15="",$AB15="", $AC15=""),"", INDEX($AB$4:$AB934,MATCH(CONCATENATE($A15,$AV15),$A$4:$A934&$AC$4:$AC934,0),1)) -> 00009-2026-OEFA/DSAP | AV15: {=IF(OR($A15="",$AB15="", $AC15=""),"",MAXA(IF($A15=$A$4:$A923,$AC$4:$AC923)))} -> 46080
A16: 0223-2022-ACTA 0003-3-CAGR | B16: =IF(A16="","",IF(E16="","INDICAR NÚMERO DE PROYECTO",CONCATENATE("MULTA COERCITIVA - ",E16,"/",F16))) -> MULTA COERCITIVA - 9/CÓDIGO DE EXPEDIENTE INVÁLIDO | C16: PEÑA, AGUSTÍN | D16: =IF(A16="","",IF(AL16<>"","EN ETAPA DE COBRANZA",IF(AH16<>"","EN SEGUIMIENTO DE MULTA",IF(AB16<>"","EN IMPOISICIÓN DE MULTA",IF(Q16<>"","EN ETAPA DE ÁNALISIS DE DESCARGOS",IF(OR(P17="VENCIDO", P17="EN PLAZO"),"EN ETAPA DE DESCARGOS","EN ETAPA DE DESCARGOS")))))) -> EN ETAPA DE COBRANZA | E16: 9 | F16: {=IF($A16="","",IFERROR(INDEX(MA_INDIVIDUALES!C$2:C923, MATCH($A16,MA_INDIVIDUALES!$B$2:$B923,0),1),"CÓDIGO DE EXPEDIENTE INVÁLIDO"))} -> CÓDIGO DE EXPEDIENTE INVÁLIDO | G16: {=IF($A16="","",IFERROR(INDEX(MA_INDIVIDUALES!K$2:K923, MATCH($A16,MA_INDIVIDUALES!$B$2:$B923,0),1),"CÓDIGO DE EXPEDIENTE INVÁLIDO"))} -> CÓDIGO DE EXPEDIENTE INVÁLIDO | H16: {=IF($A16="","",IFERROR(INDEX(MA_INDIVIDUALES!L$2:L923, MATCH($A16,MA_INDIVIDUALES!$B$2:$B923,0),1),"CÓDIGO DE EXPEDIENTE INVÁLIDO"))} -> CÓDIGO DE EXPEDIENTE INVÁLIDO | I16: 0218-2024-DSAP-CAGR | J16: 00078-2025-OEFA/DSAP | K16: 45684 | L16: =IF(A16="","",IF(K16="","",_xlfn.WORKDAY.INTL(K16,5,1,FERIADOS))) -> 45691 | M16: NO | P16: =IF(A16="","",IF(M16="NO","NO PRESENTÓ DESCARGOS",IF(N16="",IF(TODAY()<=L16,"EN PLAZO","VENCIDO"),IF(N16<=L16,"PRESENTADO EN PLAZO","PRESENTADO FUERA DE PLAZO")))) -> NO PRESENTÓ DESCARGOS | U16: SI | Y16: =IF(A16="","",IF(U16="SI","ELABORAR MC",IF(U16="NO","NO AMERITA ELABORAR MC","EN PROCESO"))) -> ELABORAR MC | Z16: =IF(A16="","",IF(AND(AR16=-1,Y16="ELABORAR MC"),"SIN REGISTRO DE ETAPAS",IF(AND(AR16=0,Y16="ELABORAR MC"),"EN PROCESO",IF(AND(AR16=1,Y16="ELABORAR MC",AB16=""),"EN ESPERA DE REGISTRO DE RESOLUCIÓN",IF(AND(AR16=1,Y16="ELABORAR MC",AB16<>""),"TERMINADO",IF(OR(Y16="NO AMERITA MC",Y16="EN PROCESO"),"","")))))) -> SIN REGISTRO DE ETAPAS | AA16: 0218-2024-DSAP-CAGR | AB16: 00009-2026-OEFA/DSAP | AC16: 46080 | AD16: 46080 | AE16: =IF(U16="","",IF(AD16="","",_xlfn.WORKDAY.INTL(AD16,7,1,FERIADOS))) -> 46091 | AF16: 1 | AG16: {=IF(A16="","",IF(AF16="","",AF16*INDEX(PARAMETROS!F$2:F1079,MATCH(YEAR(AC16),PARAMETROS!E$2:E1079,0),1)))} -> #N/A | AL16: INCUMPLIDO | AQ16: =IF($A16="","",IF(OR(AB16="",AL16="EN EJECUCIÓN"),"EN PROCESO", IF(AE16="","INDICAR FECHA DE NOTIFICACIÓN",IF(AM16="","NO PAGÓ MULTA",IF(AM16="",IF(TODAY()<=AE16,"EN PLAZO","VENCIDO"),IF(AM16<=AE16,"PAGADO EN PLAZO","PAGADO FUERA DE PLAZO")))))) -> NO PAGÓ MULTA | AR16: {=IF(A16="","",IFERROR(INDEX('2) Etapas'!L$3:L923,MATCH(B16,'2) Etapas'!$A$4:$A923,0),1),-1))} -> -1 | AS16: =IF(A16="","",A16) -> 0223-2022-ACTA 0003-3-CAGR | AT16: =IF(A16="","",IF(AU16="","MULTA EN ELABORACIÓN", "MULTA IMPUESTA")) -> MULTA IMPUESTA | AU16: =IF(OR($A16="",$AB16="", $AC16=""),"", INDEX($AB$4:$AB935,MATCH(CONCATENATE($A16,$AV16),$A$4:$A935&$AC$4:$AC935,0),1)) -> 00009-2026-OEFA/DSAP | AV16: {=IF(OR($A16="",$AB16="", $AC16=""),"",MAXA(IF($A16=$A$4:$A923,$AC$4:$AC923)))} -> 46080
A17: 0033-2024-0037-2025-1-CAGR | B17: =IF(A17="","",IF(E17="","INDICAR NÚMERO DE PROYECTO",CONCATENATE("MULTA COERCITIVA - ",E17,"/",F17))) -> MULTA COERCITIVA - 10/CÓDIGO DE EXPEDIENTE INVÁLIDO | C17: ASCON, ALEX | D17: =IF(A17="","",IF(AL17<>"","EN ETAPA DE COBRANZA",IF(AH17<>"","EN SEGUIMIENTO DE MULTA",IF(AB17<>"","EN IMPOISICIÓN DE MULTA",IF(Q17<>"","EN ETAPA DE ÁNALISIS DE DESCARGOS",IF(OR(P18="VENCIDO", P18="EN PLAZO"),"EN ETAPA DE DESCARGOS","EN ETAPA DE DESCARGOS")))))) -> EN ETAPA DE COBRANZA | E17: 10 | F17: {=IF($A17="","",IFERROR(INDEX(MA_INDIVIDUALES!C$2:C923, MATCH($A17,MA_INDIVIDUALES!$B$2:$B923,0),1),"CÓDIGO DE EXPEDIENTE INVÁLIDO"))} -> CÓDIGO DE EXPEDIENTE INVÁLIDO | G17: {=IF($A17="","",IFERROR(INDEX(MA_INDIVIDUALES!K$2:K923, MATCH($A17,MA_INDIVIDUALES!$B$2:$B923,0),1),"CÓDIGO DE EXPEDIENTE INVÁLIDO"))} -> CÓDIGO DE EXPEDIENTE INVÁLIDO | H17: {=IF($A17="","",IFERROR(INDEX(MA_INDIVIDUALES!L$2:L923, MATCH($A17,MA_INDIVIDUALES!$B$2:$B923,0),1),"CÓDIGO DE EXPEDIENTE INVÁLIDO"))} -> CÓDIGO DE EXPEDIENTE INVÁLIDO | I17: 0033-2024-DSAP-CAGR | J17: 00041-2026-OEFA/DSAP | K17: 46056 | L17: =IF(A17="","",IF(K17="","",_xlfn.WORKDAY.INTL(K17,5,1,FERIADOS))) -> 46063 | M17: NO | P17: =IF(A17="","",IF(M17="NO","NO PRESENTÓ DESCARGOS",IF(N17="",IF(TODAY()<=L17,"EN PLAZO","VENCIDO"),IF(N17<=L17,"PRESENTADO EN PLAZO","PRESENTADO FUERA DE PLAZO")))) -> NO PRESENTÓ DESCARGOS | U17: SI | Y17: =IF(A17="","",IF(U17="SI","ELABORAR MC",IF(U17="NO","NO AMERITA ELABORAR MC","EN PROCESO"))) -> ELABORAR MC | Z17: =IF(A17="","",IF(AND(AR17=-1,Y17="ELABORAR MC"),"SIN REGISTRO DE ETAPAS",IF(AND(AR17=0,Y17="ELABORAR MC"),"EN PROCESO",IF(AND(AR17=1,Y17="ELABORAR MC",AB17=""),"EN ESPERA DE REGISTRO DE RESOLUCIÓN",IF(AND(AR17=1,Y17="ELABORAR MC",AB17<>""),"TERMINADO",IF(OR(Y17="NO AMERITA MC",Y17="EN PROCESO"),"","")))))) -> SIN REGISTRO DE ETAPAS | AA17: 0033-2024-DSAP-CAGR | AB17: 00010-2026-OEFA/DSAP | AC17: 46087 | AD17: 46090 | AE17: =IF(U17="","",IF(AD17="","",_xlfn.WORKDAY.INTL(AD17,7,1,FERIADOS))) -> 46099 | AF17: 2.75 | AG17: {=IF(A17="","",IF(AF17="","",AF17*INDEX(PARAMETROS!F$2:F1080,MATCH(YEAR(AC17),PARAMETROS!E$2:E1080,0),1)))} -> #N/A | AL17: INCUMPLIDO | AN17: 00850-2026-OEFA/DSAP | AO17: 46139 | AP17: 2026-I01-014643 | AQ17: =IF($A17="","",IF(OR(AB17="",AL17="EN EJECUCIÓN"),"EN PROCESO", IF(AE17="","INDICAR FECHA DE NOTIFICACIÓN",IF(AM17="","NO PAGÓ MULTA",IF(AM17="",IF(TODAY()<=AE17,"EN PLAZO","VENCIDO"),IF(AM17<=AE17,"PAGADO EN PLAZO","PAGADO FUERA DE PLAZO")))))) -> NO PAGÓ MULTA | AR17: {=IF(A17="","",IFERROR(INDEX('2) Etapas'!L$3:L923,MATCH(B17,'2) Etapas'!$A$4:$A923,0),1),-1))} -> -1 | AS17: =IF(A17="","",A17) -> 0033-2024-0037-2025-1-CAGR | AT17: =IF(A17="","",IF(AU17="","MULTA EN ELABORACIÓN", "MULTA IMPUESTA")) -> MULTA IMPUESTA | AU17: =IF(OR($A17="",$AB17="", $AC17=""),"", INDEX($AB$4:$AB936,MATCH(CONCATENATE($A17,$AV17),$A$4:$A936&$AC$4:$AC936,0),1)) -> 00010-2026-OEFA/DSAP | AV17: {=IF(OR($A17="",$AB17="", $AC17=""),"",MAXA(IF($A17=$A$4:$A923,$AC$4:$AC923)))} -> 46087
A18: 0033-2024-0037-2025-2-CAGR | B18: =IF(A18="","",IF(E18="","INDICAR NÚMERO DE PROYECTO",CONCATENATE("MULTA COERCITIVA - ",E18,"/",F18))) -> MULTA COERCITIVA - 10/CÓDIGO DE EXPEDIENTE INVÁLIDO | C18: ASCON, ALEX | D18: =IF(A18="","",IF(AL18<>"","EN ETAPA DE COBRANZA",IF(AH18<>"","EN SEGUIMIENTO DE MULTA",IF(AB18<>"","EN IMPOISICIÓN DE MULTA",IF(Q18<>"","EN ETAPA DE ÁNALISIS DE DESCARGOS",IF(OR(P19="VENCIDO", P19="EN PLAZO"),"EN ETAPA DE DESCARGOS","EN ETAPA DE DESCARGOS")))))) -> EN ETAPA DE COBRANZA | E18: 10 | F18: {=IF($A18="","",IFERROR(INDEX(MA_INDIVIDUALES!C$2:C923, MATCH($A18,MA_INDIVIDUALES!$B$2:$B923,0),1),"CÓDIGO DE EXPEDIENTE INVÁLIDO"))} -> CÓDIGO DE EXPEDIENTE INVÁLIDO | G18: {=IF($A18="","",IFERROR(INDEX(MA_INDIVIDUALES!K$2:K923, MATCH($A18,MA_INDIVIDUALES!$B$2:$B923,0),1),"CÓDIGO DE EXPEDIENTE INVÁLIDO"))} -> CÓDIGO DE EXPEDIENTE INVÁLIDO | H18: {=IF($A18="","",IFERROR(INDEX(MA_INDIVIDUALES!L$2:L923, MATCH($A18,MA_INDIVIDUALES!$B$2:$B923,0),1),"CÓDIGO DE EXPEDIENTE INVÁLIDO"))} -> CÓDIGO DE EXPEDIENTE INVÁLIDO | I18: 0033-2024-DSAP-CAGR | J18: 00041-2026-OEFA/DSAP | K18: 46056 | L18: =IF(A18="","",IF(K18="","",_xlfn.WORKDAY.INTL(K18,5,1,FERIADOS))) -> 46063 | M18: NO | P18: =IF(A18="","",IF(M18="NO","NO PRESENTÓ DESCARGOS",IF(N18="",IF(TODAY()<=L18,"EN PLAZO","VENCIDO"),IF(N18<=L18,"PRESENTADO EN PLAZO","PRESENTADO FUERA DE PLAZO")))) -> NO PRESENTÓ DESCARGOS | U18: SI | Y18: =IF(A18="","",IF(U18="SI","ELABORAR MC",IF(U18="NO","NO AMERITA ELABORAR MC","EN PROCESO"))) -> ELABORAR MC | Z18: =IF(A18="","",IF(AND(AR18=-1,Y18="ELABORAR MC"),"SIN REGISTRO DE ETAPAS",IF(AND(AR18=0,Y18="ELABORAR MC"),"EN PROCESO",IF(AND(AR18=1,Y18="ELABORAR MC",AB18=""),"EN ESPERA DE REGISTRO DE RESOLUCIÓN",IF(AND(AR18=1,Y18="ELABORAR MC",AB18<>""),"TERMINADO",IF(OR(Y18="NO AMERITA MC",Y18="EN PROCESO"),"","")))))) -> SIN REGISTRO DE ETAPAS | AA18: 0033-2024-DSAP-CAGR | AB18: 00010-2026-OEFA/DSAP | AC18: 46087 | AD18: 46090 | AE18: =IF(U18="","",IF(AD18="","",_xlfn.WORKDAY.INTL(AD18,7,1,FERIADOS))) -> 46099 | AF18: 2.75 | AG18: {=IF(A18="","",IF(AF18="","",AF18*INDEX(PARAMETROS!F$2:F1081,MATCH(YEAR(AC18),PARAMETROS!E$2:E1081,0),1)))} -> #N/A | AL18: INCUMPLIDO | AN18: 00850-2026-OEFA/DSAP | AO18: 46139 | AP18: 2026-I01-014643 | AQ18: =IF($A18="","",IF(OR(AB18="",AL18="EN EJECUCIÓN"),"EN PROCESO", IF(AE18="","INDICAR FECHA DE NOTIFICACIÓN",IF(AM18="","NO PAGÓ MULTA",IF(AM18="",IF(TODAY()<=AE18,"EN PLAZO","VENCIDO"),IF(AM18<=AE18,"PAGADO EN PLAZO","PAGADO FUERA DE PLAZO")))))) -> NO PAGÓ MULTA | AR18: {=IF(A18="","",IFERROR(INDEX('2) Etapas'!L$3:L923,MATCH(B18,'2) Etapas'!$A$4:$A923,0),1),-1))} -> -1 | AS18: =IF(A18="","",A18) -> 0033-2024-0037-2025-2-CAGR | AT18: =IF(A18="","",IF(AU18="","MULTA EN ELABORACIÓN", "MULTA IMPUESTA")) -> MULTA IMPUESTA | AU18: =IF(OR($A18="",$AB18="", $AC18=""),"", INDEX($AB$4:$AB937,MATCH(CONCATENATE($A18,$AV18),$A$4:$A937&$AC$4:$AC937,0),1)) -> 00010-2026-OEFA/DSAP | AV18: {=IF(OR($A18="",$AB18="", $AC18=""),"",MAXA(IF($A18=$A$4:$A923,$AC$4:$AC923)))} -> 46087
A19: 0184-2024-0019-2025-1-CAGR | B19: =IF(A19="","",IF(E19="","INDICAR NÚMERO DE PROYECTO",CONCATENATE("MULTA COERCITIVA - ",E19,"/",F19))) -> MULTA COERCITIVA - 11/CÓDIGO DE EXPEDIENTE INVÁLIDO | C19: CORCUERA, ALDO | D19: =IF(A19="","",IF(AL19<>"","EN ETAPA DE COBRANZA",IF(AH19<>"","EN SEGUIMIENTO DE MULTA",IF(AB19<>"","EN IMPOISICIÓN DE MULTA",IF(Q19<>"","EN ETAPA DE ÁNALISIS DE DESCARGOS",IF(OR(P20="VENCIDO", P20="EN PLAZO"),"EN ETAPA DE DESCARGOS","EN ETAPA DE DESCARGOS")))))) -> EN ETAPA DE COBRANZA | E19: 11 | F19: {=IF($A19="","",IFERROR(INDEX(MA_INDIVIDUALES!C$2:C923, MATCH($A19,MA_INDIVIDUALES!$B$2:$B923,0),1),"CÓDIGO DE EXPEDIENTE INVÁLIDO"))} -> CÓDIGO DE EXPEDIENTE INVÁLIDO | G19: {=IF($A19="","",IFERROR(INDEX(MA_INDIVIDUALES!K$2:K923, MATCH($A19,MA_INDIVIDUALES!$B$2:$B923,0),1),"CÓDIGO DE EXPEDIENTE INVÁLIDO"))} -> CÓDIGO DE EXPEDIENTE INVÁLIDO | H19: {=IF($A19="","",IFERROR(INDEX(MA_INDIVIDUALES!L$2:L923, MATCH($A19,MA_INDIVIDUALES!$B$2:$B923,0),1),"CÓDIGO DE EXPEDIENTE INVÁLIDO"))} -> CÓDIGO DE EXPEDIENTE INVÁLIDO | I19: 0180-2025-DSAP-CAGR | J19: 00539-2026-OEFA/DSAP | K19: 46182 | L19: =IF(A19="","",IF(K19="","",_xlfn.WORKDAY.INTL(K19,5,1,FERIADOS))) -> 46189 | M19: NO | P19: =IF(A19="","",IF(M19="NO","NO PRESENTÓ DESCARGOS",IF(N19="",IF(TODAY()<=L19,"EN PLAZO","VENCIDO"),IF(N19<=L19,"PRESENTADO EN PLAZO","PRESENTADO FUERA DE PLAZO")))) -> NO PRESENTÓ DESCARGOS | U19: SI | Y19: =IF(A19="","",IF(U19="SI","ELABORAR MC",IF(U19="NO","NO AMERITA ELABORAR MC","EN PROCESO"))) -> ELABORAR MC | Z19: =IF(A19="","",IF(AND(AR19=-1,Y19="ELABORAR MC"),"SIN REGISTRO DE ETAPAS",IF(AND(AR19=0,Y19="ELABORAR MC"),"EN PROCESO",IF(AND(AR19=1,Y19="ELABORAR MC",AB19=""),"EN ESPERA DE REGISTRO DE RESOLUCIÓN",IF(AND(AR19=1,Y19="ELABORAR MC",AB19<>""),"TERMINADO",IF(OR(Y19="NO AMERITA MC",Y19="EN PROCESO"),"","")))))) -> SIN REGISTRO DE ETAPAS | AA19: 0180-2025-DSAP-CAGR | AB19: 0016-2026-OEFA/DSAP | AC19: 46203 | AD19: 46203 | AE19: =IF(U19="","",IF(AD19="","",_xlfn.WORKDAY.INTL(AD19,7,1,FERIADOS))) -> 46212 | AF19: 5.425 | AG19: {=IF(A19="","",IF(AF19="","",AF19*INDEX(PARAMETROS!F$2:F1082,MATCH(YEAR(AC19),PARAMETROS!E$2:E1082,0),1)))} -> #N/A | AL19: EN EJECUCIÓN | AQ19: =IF($A19="","",IF(OR(AB19="",AL19="EN EJECUCIÓN"),"EN PROCESO", IF(AE19="","INDICAR FECHA DE NOTIFICACIÓN",IF(AM19="","NO PAGÓ MULTA",IF(AM19="",IF(TODAY()<=AE19,"EN PLAZO","VENCIDO"),IF(AM19<=AE19,"PAGADO EN PLAZO","PAGADO FUERA DE PLAZO")))))) -> EN PROCESO | AR19: {=IF(A19="","",IFERROR(INDEX('2) Etapas'!L$3:L923,MATCH(B19,'2) Etapas'!$A$4:$A923,0),1),-1))} -> -1 | AS19: =IF(A19="","",A19) -> 0184-2024-0019-2025-1-CAGR | AT19: =IF(A19="","",IF(AU19="","MULTA EN ELABORACIÓN", "MULTA IMPUESTA")) -> MULTA IMPUESTA | AU19: =IF(OR($A19="",$AB19="", $AC19=""),"", INDEX($AB$4:$AB938,MATCH(CONCATENATE($A19,$AV19),$A$4:$A938&$AC$4:$AC938,0),1)) -> 0016-2026-OEFA/DSAP | AV19: {=IF(OR($A19="",$AB19="", $AC19=""),"",MAXA(IF($A19=$A$4:$A923,$AC$4:$AC923)))} -> 46203
B20: =IF(A20="","",IF(E20="","INDICAR NÚMERO DE PROYECTO",CONCATENATE("MULTA COERCITIVA - ",E20,"/",F20))) | D20: =IF(A20="","",IF(AL20<>"","EN ETAPA DE COBRANZA",IF(AH20<>"","EN SEGUIMIENTO DE MULTA",IF(AB20<>"","EN IMPOISICIÓN DE MULTA",IF(Q20<>"","EN ETAPA DE ÁNALISIS DE DESCARGOS",IF(OR(P21="VENCIDO", P21="EN PLAZO"),"EN ETAPA DE DESCARGOS","EN ETAPA DE DESCARGOS")))))) | F20: {=IF($A20="","",IFERROR(INDEX(MA_INDIVIDUALES!C$2:C923, MATCH($A20,MA_INDIVIDUALES!$B$2:$B923,0),1),"CÓDIGO DE EXPEDIENTE INVÁLIDO"))} | G20: {=IF($A20="","",IFERROR(INDEX(MA_INDIVIDUALES!K$2:K923, MATCH($A20,MA_INDIVIDUALES!$B$2:$B923,0),1),"CÓDIGO DE EXPEDIENTE INVÁLIDO"))} | H20: {=IF($A20="","",IFERROR(INDEX(MA_INDIVIDUALES!L$2:L923, MATCH($A20,MA_INDIVIDUALES!$B$2:$B923,0),1),"CÓDIGO DE EXPEDIENTE INVÁLIDO"))} | L20: =IF(A20="","",IF(K20="","",_xlfn.WORKDAY.INTL(K20,5,1,FERIADOS))) | P20: =IF(A20="","",IF(M20="NO","NO PRESENTÓ DESCARGOS",IF(N20="",IF(TODAY()<=L20,"EN PLAZO","VENCIDO"),IF(N20<=L20,"PRESENTADO EN PLAZO","PRESENTADO FUERA DE PLAZO")))) | Y20: =IF(A20="","",IF(U20="SI","ELABORAR MC",IF(U20="NO","NO AMERITA ELABORAR MC","EN PROCESO"))) | Z20: =IF(A20="","",IF(AND(AR20=-1,Y20="ELABORAR MC"),"SIN REGISTRO DE ETAPAS",IF(AND(AR20=0,Y20="ELABORAR MC"),"EN PROCESO",IF(AND(AR20=1,Y20="ELABORAR MC",AB20=""),"EN ESPERA DE REGISTRO DE RESOLUCIÓN",IF(AND(AR20=1,Y20="ELABORAR MC",AB20<>""),"TERMINADO",IF(OR(Y20="NO AMERITA MC",Y20="EN PROCESO"),"","")))))) | AE20: =IF(U20="","",IF(AD20="","",_xlfn.WORKDAY.INTL(AD20,7,1,FERIADOS))) | AG20: {=IF(A20="","",IF(AF20="","",AF20*INDEX(PARAMETROS!F$2:F1083,MATCH(YEAR(AC20),PARAMETROS!E$2:E1083,0),1)))} | AQ20: =IF($A20="","",IF(OR(AB20="",AL20="EN EJECUCIÓN"),"EN PROCESO", IF(AE20="","INDICAR FECHA DE NOTIFICACIÓN",IF(AM20="","NO PAGÓ MULTA",IF(AM20="",IF(TODAY()<=AE20,"EN PLAZO","VENCIDO"),IF(AM20<=AE20,"PAGADO EN PLAZO","PAGADO FUERA DE PLAZO")))))) | AR20: {=IF(A20="","",IFERROR(INDEX('2) Etapas'!L$3:L923,MATCH(B20,'2) Etapas'!$A$4:$A923,0),1),-1))} | AS20: =IF(A20="","",A20) | AT20: =IF(A20="","",IF(AU20="","MULTA EN ELABORACIÓN", "MULTA IMPUESTA")) | AU20: =IF(OR($A20="",$AB20="", $AC20=""),"", INDEX($AB$4:$AB939,MATCH(CONCATENATE($A20,$AV20),$A$4:$A939&$AC$4:$AC939,0),1)) | AV20: {=IF(OR($A20="",$AB20="", $AC20=""),"",MAXA(IF($A20=$A$4:$A923,$AC$4:$AC923)))}
B21: =IF(A21="","",IF(E21="","INDICAR NÚMERO DE PROYECTO",CONCATENATE("MULTA COERCITIVA - ",E21,"/",F21))) | D21: =IF(A21="","",IF(AL21<>"","EN ETAPA DE COBRANZA",IF(AH21<>"","EN SEGUIMIENTO DE MULTA",IF(AB21<>"","EN IMPOISICIÓN DE MULTA",IF(Q21<>"","EN ETAPA DE ÁNALISIS DE DESCARGOS",IF(OR(P22="VENCIDO", P22="EN PLAZO"),"EN ETAPA DE DESCARGOS","EN ETAPA DE DESCARGOS")))))) | F21: {=IF($A21="","",IFERROR(INDEX(MA_INDIVIDUALES!C$2:C923, MATCH($A21,MA_INDIVIDUALES!$B$2:$B923,0),1),"CÓDIGO DE EXPEDIENTE INVÁLIDO"))} | G21: {=IF($A21="","",IFERROR(INDEX(MA_INDIVIDUALES!K$2:K923, MATCH($A21,MA_INDIVIDUALES!$B$2:$B923,0),1),"CÓDIGO DE EXPEDIENTE INVÁLIDO"))} | H21: {=IF($A21="","",IFERROR(INDEX(MA_INDIVIDUALES!L$2:L923, MATCH($A21,MA_INDIVIDUALES!$B$2:$B923,0),1),"CÓDIGO DE EXPEDIENTE INVÁLIDO"))} | L21: =IF(A21="","",IF(K21="","",_xlfn.WORKDAY.INTL(K21,5,1,FERIADOS))) | P21: =IF(A21="","",IF(M21="NO","NO PRESENTÓ DESCARGOS",IF(N21="",IF(TODAY()<=L21,"EN PLAZO","VENCIDO"),IF(N21<=L21,"PRESENTADO EN PLAZO","PRESENTADO FUERA DE PLAZO")))) | Y21: =IF(A21="","",IF(U21="SI","ELABORAR MC",IF(U21="NO","NO AMERITA ELABORAR MC","EN PROCESO"))) | Z21: =IF(A21="","",IF(AND(AR21=-1,Y21="ELABORAR MC"),"SIN REGISTRO DE ETAPAS",IF(AND(AR21=0,Y21="ELABORAR MC"),"EN PROCESO",IF(AND(AR21=1,Y21="ELABORAR MC",AB21=""),"EN ESPERA DE REGISTRO DE RESOLUCIÓN",IF(AND(AR21=1,Y21="ELABORAR MC",AB21<>""),"TERMINADO",IF(OR(Y21="NO AMERITA MC",Y21="EN PROCESO"),"","")))))) | AE21: =IF(U21="","",IF(AD21="","",_xlfn.WORKDAY.INTL(AD21,7,1,FERIADOS))) | AG21: {=IF(A21="","",IF(AF21="","",AF21*INDEX(PARAMETROS!F$2:F1084,MATCH(YEAR(AC21),PARAMETROS!E$2:E1084,0),1)))} | AQ21: =IF($A21="","",IF(OR(AB21="",AL21="EN EJECUCIÓN"),"EN PROCESO", IF(AE21="","INDICAR FECHA DE NOTIFICACIÓN",IF(AM21="","NO PAGÓ MULTA",IF(AM21="",IF(TODAY()<=AE21,"EN PLAZO","VENCIDO"),IF(AM21<=AE21,"PAGADO EN PLAZO","PAGADO FUERA DE PLAZO")))))) | AR21: {=IF(A21="","",IFERROR(INDEX('2) Etapas'!L$3:L923,MATCH(B21,'2) Etapas'!$A$4:$A923,0),1),-1))} | AS21: =IF(A21="","",A21) | AT21: =IF(A21="","",IF(AU21="","MULTA EN ELABORACIÓN", "MULTA IMPUESTA")) | AU21: =IF(OR($A21="",$AB21="", $AC21=""),"", INDEX($AB$4:$AB940,MATCH(CONCATENATE($A21,$AV21),$A$4:$A940&$AC$4:$AC940,0),1)) | AV21: {=IF(OR($A21="",$AB21="", $AC21=""),"",MAXA(IF($A21=$A$4:$A923,$AC$4:$AC923)))}
B22: =IF(A22="","",IF(E22="","INDICAR NÚMERO DE PROYECTO",CONCATENATE("MULTA COERCITIVA - ",E22,"/",F22))) | D22: =IF(A22="","",IF(AL22<>"","EN ETAPA DE COBRANZA",IF(AH22<>"","EN SEGUIMIENTO DE MULTA",IF(AB22<>"","EN IMPOISICIÓN DE MULTA",IF(Q22<>"","EN ETAPA DE ÁNALISIS DE DESCARGOS",IF(OR(P23="VENCIDO", P23="EN PLAZO"),"EN ETAPA DE DESCARGOS","EN ETAPA DE DESCARGOS")))))) | F22: {=IF($A22="","",IFERROR(INDEX(MA_INDIVIDUALES!C$2:C923, MATCH($A22,MA_INDIVIDUALES!$B$2:$B923,0),1),"CÓDIGO DE EXPEDIENTE INVÁLIDO"))} | G22: {=IF($A22="","",IFERROR(INDEX(MA_INDIVIDUALES!K$2:K923, MATCH($A22,MA_INDIVIDUALES!$B$2:$B923,0),1),"CÓDIGO DE EXPEDIENTE INVÁLIDO"))} | H22: {=IF($A22="","",IFERROR(INDEX(MA_INDIVIDUALES!L$2:L923, MATCH($A22,MA_INDIVIDUALES!$B$2:$B923,0),1),"CÓDIGO DE EXPEDIENTE INVÁLIDO"))} | L22: =IF(A22="","",IF(K22="","",_xlfn.WORKDAY.INTL(K22,5,1,FERIADOS))) | P22: =IF(A22="","",IF(M22="NO","NO PRESENTÓ DESCARGOS",IF(N22="",IF(TODAY()<=L22,"EN PLAZO","VENCIDO"),IF(N22<=L22,"PRESENTADO EN PLAZO","PRESENTADO FUERA DE PLAZO")))) | Y22: =IF(A22="","",IF(U22="SI","ELABORAR MC",IF(U22="NO","NO AMERITA ELABORAR MC","EN PROCESO"))) | Z22: =IF(A22="","",IF(AND(AR22=-1,Y22="ELABORAR MC"),"SIN REGISTRO DE ETAPAS",IF(AND(AR22=0,Y22="ELABORAR MC"),"EN PROCESO",IF(AND(AR22=1,Y22="ELABORAR MC",AB22=""),"EN ESPERA DE REGISTRO DE RESOLUCIÓN",IF(AND(AR22=1,Y22="ELABORAR MC",AB22<>""),"TERMINADO",IF(OR(Y22="NO AMERITA MC",Y22="EN PROCESO"),"","")))))) | AE22: =IF(U22="","",IF(AD22="","",_xlfn.WORKDAY.INTL(AD22,7,1,FERIADOS))) | AG22: {=IF(A22="","",IF(AF22="","",AF22*INDEX(PARAMETROS!F$2:F1085,MATCH(YEAR(AC22),PARAMETROS!E$2:E1085,0),1)))} | AQ22: =IF($A22="","",IF(OR(AB22="",AL22="EN EJECUCIÓN"),"EN PROCESO", IF(AE22="","INDICAR FECHA DE NOTIFICACIÓN",IF(AM22="","NO PAGÓ MULTA",IF(AM22="",IF(TODAY()<=AE22,"EN PLAZO","VENCIDO"),IF(AM22<=AE22,"PAGADO EN PLAZO","PAGADO FUERA DE PLAZO")))))) | AR22: {=IF(A22="","",IFERROR(INDEX('2) Etapas'!L$3:L923,MATCH(B22,'2) Etapas'!$A$4:$A923,0),1),-1))} | AS22: =IF(A22="","",A22) | AT22: =IF(A22="","",IF(AU22="","MULTA EN ELABORACIÓN", "MULTA IMPUESTA")) | AU22: =IF(OR($A22="",$AB22="", $AC22=""),"", INDEX($AB$4:$AB941,MATCH(CONCATENATE($A22,$AV22),$A$4:$A941&$AC$4:$AC941,0),1)) | AV22: {=IF(OR($A22="",$AB22="", $AC22=""),"",MAXA(IF($A22=$A$4:$A923,$AC$4:$AC923)))}
